Workbook

Sheet Inicio
C2: Control de Créditos
C3: =IF(Datos!$C$6="","Tu marca aquí (hoja Datos)",Datos!$C$6) -> Tu marca aquí (hoja Datos)
C7: Cliente | D7: =IF(Datos!$C$5="","",Datos!$C$5)
B9: Cómo se usa
B10: # | C10: Cuándo | D10: Qué hacer
B11: 1 | C11: Una sola vez | D11: Hoja Datos: ingresos y tasa de cambio. Cada hoja Crédito: nombre, saldo, fecha de la primera cuota, tasa y cuota (o plazo).
B12: 2 | C12: Cada mes | D12: En cada crédito, escribe "Sí" en Pagado y la fecha real de pago de la cuota del mes.
B13: 3 | C13: Si abonas extra | D13: Escribe el valor en la columna Abono extra del mes en que lo hiciste. El saldo y la fecha fin se recalculan.
B14: 4 | C14: Si cambia la cuota | D14: Escribe la nueva cuota en "Cuota distinta este mes" (por ejemplo, un mes con cuota especial).
B15: 5 | C15: Para revisar | D15: Panel: deuda total, pagos del mes, calendario, cuotas vencidas y el plan de pago.
B16: 6 | C16: Plan de pago | D16: Elige el método. El Panel muestra a qué crédito va el abono extra del próximo mes.
B18: Casos especiales
C19: Préstamo familiar sin interés | D19: Tasa 0% y "¿Acepta abonos extra?" = No si se acordó pagar a un ritmo fijo.
C20: Hipotecario con FRECH | D20: Escribe los puntos de tasa cubiertos y hasta qué cuota. Si no se debe abonar antes de cierta cuota, escríbela en "Abonos extra desde".
C21: Crédito que ya va avanzado | D21: Usa el saldo actual del extracto, la fecha de la próxima cuota y su número.
C22: Ingresos en dólares | D22: Hoja Datos: moneda USD y la tasa de cambio que te pagan. Mira la tabla de sensibilidad.
B24: Leyenda
C25: Dato que llenas | D25: Celda para llenar o actualizar.
C26: Por confirmar | D26: Dato pendiente de confirmar.
C27: Cálculo automático | D27: Fórmula: no se edita.
C29: Cifras en pesos. Los cálculos son una guía: confirma saldos y cuotas con los extractos de cada entidad.

Sheet Panel
B1: Panel de créditos
B2: Se actualiza solo: marca "Sí" en Pagado en cada crédito y aquí cambian saldos, calendario y proyección.
B4: Deuda total hoy | D4: Pago del próximo mes | F4: Intereses por pagar | H4: Capital ya pagado | J4: Libre de deudas (con el plan) | L4: Cuotas vencidas sin marcar
B5: ='Crédito 1'!$I$6+'Crédito 2'!$I$6+'Crédito 3'!$I$6+'Crédito 4'!$I$6+'Crédito 5'!$I$6+'Crédito 6'!$I$6+'Crédito 7'!$I$6+'Crédito 8'!$I$6 -> 0 | D5: ='Crédito 1'!$I$10+'Crédito 2'!$I$10+'Crédito 3'!$I$10+'Crédito 4'!$I$10+'Crédito 5'!$I$10+'Crédito 6'!$I$10+'Crédito 7'!$I$10+'Crédito 8'!$I$10 -> 0 | F5: ='Crédito 1'!$I$13+'Crédito 2'!$I$13+'Crédito 3'!$I$13+'Crédito 4'!$I$13+'Crédito 5'!$I$13+'Crédito 6'!$I$13+'Crédito 7'!$I$13+'Crédito 8'!$I$13 -> 0 | H5: =IF(SUM(N13:N20)=0,0,1-B5/SUM(N13:N20)) -> 0 | J5: =IF(COUNT('Plan de pago'!$M$12:$M$19)=0,"",IF(COUNTIF('Plan de pago'!$M$12:$M$19,"Más de 360")>0,"Más de 30 años",MAX('Plan de pago'!$M$12:$M$19))) | L5: ='Crédito 1'!$I$17+'Crédito 2'!$I$17+'Crédito 3'!$I$17+'Crédito 4'!$I$17+'Crédito 5'!$I$17+'Crédito 6'!$I$17+'Crédito 7'!$I$17+'Crédito 8'!$I$17 -> 0
B7: Carga financiera (deudas / ingreso): | D7: =Datos!$C$21 | E7: =Datos!$D$21
B10: 1. Resumen de créditos
B12: Crédito | C12: Saldo actual | D12: Tasa EA | E12: Próximo pago | F12: Cuotas restantes | G12: Fecha fin | H12: Intereses pendientes | I12: Total pendiente | J12: % capital pagado | K12: Estado | L12: Entidad | N12: Base %
B13: =IF('Crédito 1'!$F$6="Sí",'Crédito 1'!$C$6,"") | C13: =IF($B13="","",'Crédito 1'!$I$6) | D13: =IF($B13="","",'Crédito 1'!$C$13) | E13: =IF($B13="","",'Crédito 1'!$I$10) | F13: =IF($B13="","",'Crédito 1'!$I$11) | G13: =IF($B13="","",'Crédito 1'!$I$12) | H13: =IF($B13="","",'Crédito 1'!$I$13) | I13: =IF($B13="","",'Crédito 1'!$I$14) | J13: =IF($B13="","",'Crédito 1'!$I$15) | K13: =IF($B13="","",'Crédito 1'!$I$19) | L13: =IF($B13="","",'Crédito 1'!$C$7) | N13: =IF($B13="",0,IF(N('Crédito 1'!$C$16)>0,'Crédito 1'!$C$16,N('Crédito 1'!$C$9))) -> 0 | O13: =IF(ISNUMBER('Crédito 1'!$I$9),'Crédito 1'!$I$9+1/100,"")
B14: =IF('Crédito 2'!$F$6="Sí",'Crédito 2'!$C$6,"") | C14: =IF($B14="","",'Crédito 2'!$I$6) | D14: =IF($B14="","",'Crédito 2'!$C$13) | E14: =IF($B14="","",'Crédito 2'!$I$10) | F14: =IF($B14="","",'Crédito 2'!$I$11) | G14: =IF($B14="","",'Crédito 2'!$I$12) | H14: =IF($B14="","",'Crédito 2'!$I$13) | I14: =IF($B14="","",'Crédito 2'!$I$14) | J14: =IF($B14="","",'Crédito 2'!$I$15) | K14: =IF($B14="","",'Crédito 2'!$I$19) | L14: =IF($B14="","",'Crédito 2'!$C$7) | N14: =IF($B14="",0,IF(N('Crédito 2'!$C$16)>0,'Crédito 2'!$C$16,N('Crédito 2'!$C$9))) -> 0 | O14: =IF(ISNUMBER('Crédito 2'!$I$9),'Crédito 2'!$I$9+2/100,"")
B15: =IF('Crédito 3'!$F$6="Sí",'Crédito 3'!$C$6,"") | C15: =IF($B15="","",'Crédito 3'!$I$6) | D15: =IF($B15="","",'Crédito 3'!$C$13) | E15: =IF($B15="","",'Crédito 3'!$I$10) | F15: =IF($B15="","",'Crédito 3'!$I$11) | G15: =IF($B15="","",'Crédito 3'!$I$12) | H15: =IF($B15="","",'Crédito 3'!$I$13) | I15: =IF($B15="","",'Crédito 3'!$I$14) | J15: =IF($B15="","",'Crédito 3'!$I$15) | K15: =IF($B15="","",'Crédito 3'!$I$19) | L15: =IF($B15="","",'Crédito 3'!$C$7) | N15: =IF($B15="",0,IF(N('Crédito 3'!$C$16)>0,'Crédito 3'!$C$16,N('Crédito 3'!$C$9))) -> 0 | O15: =IF(ISNUMBER('Crédito 3'!$I$9),'Crédito 3'!$I$9+3/100,"")
B16: =IF('Crédito 4'!$F$6="Sí",'Crédito 4'!$C$6,"") | C16: =IF($B16="","",'Crédito 4'!$I$6) | D16: =IF($B16="","",'Crédito 4'!$C$13) | E16: =IF($B16="","",'Crédito 4'!$I$10) | F16: =IF($B16="","",'Crédito 4'!$I$11) | G16: =IF($B16="","",'Crédito 4'!$I$12) | H16: =IF($B16="","",'Crédito 4'!$I$13) | I16: =IF($B16="","",'Crédito 4'!$I$14) | J16: =IF($B16="","",'Crédito 4'!$I$15) | K16: =IF($B16="","",'Crédito 4'!$I$19) | L16: =IF($B16="","",'Crédito 4'!$C$7) | N16: =IF($B16="",0,IF(N('Crédito 4'!$C$16)>0,'Crédito 4'!$C$16,N('Crédito 4'!$C$9))) -> 0 | O16: =IF(ISNUMBER('Crédito 4'!$I$9),'Crédito 4'!$I$9+4/100,"")
B17: =IF('Crédito 5'!$F$6="Sí",'Crédito 5'!$C$6,"") | C17: =IF($B17="","",'Crédito 5'!$I$6) | D17: =IF($B17="","",'Crédito 5'!$C$13) | E17: =IF($B17="","",'Crédito 5'!$I$10) | F17: =IF($B17="","",'Crédito 5'!$I$11) | G17: =IF($B17="","",'Crédito 5'!$I$12) | H17: =IF($B17="","",'Crédito 5'!$I$13) | I17: =IF($B17="","",'Crédito 5'!$I$14) | J17: =IF($B17="","",'Crédito 5'!$I$15) | K17: =IF($B17="","",'Crédito 5'!$I$19) | L17: =IF($B17="","",'Crédito 5'!$C$7) | N17: =IF($B17="",0,IF(N('Crédito 5'!$C$16)>0,'Crédito 5'!$C$16,N('Crédito 5'!$C$9))) -> 0 | O17: =IF(ISNUMBER('Crédito 5'!$I$9),'Crédito 5'!$I$9+5/100,"")
B18: =IF('Crédito 6'!$F$6="Sí",'Crédito 6'!$C$6,"") | C18: =IF($B18="","",'Crédito 6'!$I$6) | D18: =IF($B18="","",'Crédito 6'!$C$13) | E18: =IF($B18="","",'Crédito 6'!$I$10) | F18: =IF($B18="","",'Crédito 6'!$I$11) | G18: =IF($B18="","",'Crédito 6'!$I$12) | H18: =IF($B18="","",'Crédito 6'!$I$13) | I18: =IF($B18="","",'Crédito 6'!$I$14) | J18: =IF($B18="","",'Crédito 6'!$I$15) | K18: =IF($B18="","",'Crédito 6'!$I$19) | L18: =IF($B18="","",'Crédito 6'!$C$7) | N18: =IF($B18="",0,IF(N('Crédito 6'!$C$16)>0,'Crédito 6'!$C$16,N('Crédito 6'!$C$9))) -> 0 | O18: =IF(ISNUMBER('Crédito 6'!$I$9),'Crédito 6'!$I$9+6/100,"")
B19: =IF('Crédito 7'!$F$6="Sí",'Crédito 7'!$C$6,"") | C19: =IF($B19="","",'Crédito 7'!$I$6) | D19: =IF($B19="","",'Crédito 7'!$C$13) | E19: =IF($B19="","",'Crédito 7'!$I$10) | F19: =IF($B19="","",'Crédito 7'!$I$11) | G19: =IF($B19="","",'Crédito 7'!$I$12) | H19: =IF($B19="","",'Crédito 7'!$I$13) | I19: =IF($B19="","",'Crédito 7'!$I$14) | J19: =IF($B19="","",'Crédito 7'!$I$15) | K19: =IF($B19="","",'Crédito 7'!$I$19) | L19: =IF($B19="","",'Crédito 7'!$C$7) | N19: =IF($B19="",0,IF(N('Crédito 7'!$C$16)>0,'Crédito 7'!$C$16,N('Crédito 7'!$C$9))) -> 0 | O19: =IF(ISNUMBER('Crédito 7'!$I$9),'Crédito 7'!$I$9+7/100,"")
B20: =IF('Crédito 8'!$F$6="Sí",'Crédito 8'!$C$6,"") | C20: =IF($B20="","",'Crédito 8'!$I$6) | D20: =IF($B20="","",'Crédito 8'!$C$13) | E20: =IF($B20="","",'Crédito 8'!$I$10) | F20: =IF($B20="","",'Crédito 8'!$I$11) | G20: =IF($B20="","",'Crédito 8'!$I$12) | H20: =IF($B20="","",'Crédito 8'!$I$13) | I20: =IF($B20="","",'Crédito 8'!$I$14) | J20: =IF($B20="","",'Crédito 8'!$I$15) | K20: =IF($B20="","",'Crédito 8'!$I$19) | L20: =IF($B20="","",'Crédito 8'!$C$7) | N20: =IF($B20="",0,IF(N('Crédito 8'!$C$16)>0,'Crédito 8'!$C$16,N('Crédito 8'!$C$9))) -> 0 | O20: =IF(ISNUMBER('Crédito 8'!$I$9),'Crédito 8'!$I$9+8/100,"")
B21: Total | C21: =SUM(C13:C20) -> 0 | E21: =SUM(E13:E20) -> 0 | H21: =SUM(H13:H20) -> 0 | I21: =SUM(I13:I20) -> 0
B23: 2. Calendario: próxima cuota de cada crédito (ordenado por fecha) | I23: 3. Pagos según el día del mes
B24: Crédito | C24: Próxima fecha | D24: Monto a pagar | E24: Día | F24: Estado
B25: =IF(IFERROR(MATCH(SMALL($O$13:$O$20,1),$O$13:$O$20,0),0)=0,"",INDEX($B$13:$B$20,IFERROR(MATCH(SMALL($O$13:$O$20,1),$O$13:$O$20,0),0))) | C25: =IF(B25="","",CHOOSE(IFERROR(MATCH(SMALL($O$13:$O$20,1),$O$13:$O$20,0),0),'Crédito 1'!$I$9,'Crédito 2'!$I$9,'Crédito 3'!$I$9,'Crédito 4'!$I$9,'Crédito 5'!$I$9,'Crédito 6'!$I$9,'Crédito 7'!$I$9,'Crédito 8'!$I$9)) | D25: =IF(B25="","",CHOOSE(IFERROR(MATCH(SMALL($O$13:$O$20,1),$O$13:$O$20,0),0),'Crédito 1'!$I$10,'Crédito 2'!$I$10,'Crédito 3'!$I$10,'Crédito 4'!$I$10,'Crédito 5'!$I$10,'Crédito 6'!$I$10,'Crédito 7'!$I$10,'Crédito 8'!$I$10)) | E25: =IF(B25="","",DAY(C25)) | F25: =IF(B25="","",IF(C25<Datos!$C$7,"Vencida",IF(C25-Datos!$C$7<=7,"Paga esta semana","Al día"))) | I25: Días 1 a 10 | K25: =SUMIFS($D$25:$D$32,$E$25:$E$32,">=1",$E$25:$E$32,"<=10") -> 0
B26: =IF(IFERROR(MATCH(SMALL($O$13:$O$20,2),$O$13:$O$20,0),0)=0,"",INDEX($B$13:$B$20,IFERROR(MATCH(SMALL($O$13:$O$20,2),$O$13:$O$20,0),0))) | C26: =IF(B26="","",CHOOSE(IFERROR(MATCH(SMALL($O$13:$O$20,2),$O$13:$O$20,0),0),'Crédito 1'!$I$9,'Crédito 2'!$I$9,'Crédito 3'!$I$9,'Crédito 4'!$I$9,'Crédito 5'!$I$9,'Crédito 6'!$I$9,'Crédito 7'!$I$9,'Crédito 8'!$I$9)) | D26: =IF(B26="","",CHOOSE(IFERROR(MATCH(SMALL($O$13:$O$20,2),$O$13:$O$20,0),0),'Crédito 1'!$I$10,'Crédito 2'!$I$10,'Crédito 3'!$I$10,'Crédito 4'!$I$10,'Crédito 5'!$I$10,'Crédito 6'!$I$10,'Crédito 7'!$I$10,'Crédito 8'!$I$10)) | E26: =IF(B26="","",DAY(C26)) | F26: =IF(B26="","",IF(C26<Datos!$C$7,"Vencida",IF(C26-Datos!$C$7<=7,"Paga esta semana","Al día"))) | I26: Días 11 a 20 | K26: =SUMIFS($D$25:$D$32,$E$25:$E$32,">=11",$E$25:$E$32,"<=20") -> 0
B27: =IF(IFERROR(MATCH(SMALL($O$13:$O$20,3),$O$13:$O$20,0),0)=0,"",INDEX($B$13:$B$20,IFERROR(MATCH(SMALL($O$13:$O$20,3),$O$13:$O$20,0),0))) | C27: =IF(B27="","",CHOOSE(IFERROR(MATCH(SMALL($O$13:$O$20,3),$O$13:$O$20,0),0),'Crédito 1'!$I$9,'Crédito 2'!$I$9,'Crédito 3'!$I$9,'Crédito 4'!$I$9,'Crédito 5'!$I$9,'Crédito 6'!$I$9,'Crédito 7'!$I$9,'Crédito 8'!$I$9)) | D27: =IF(B27="","",CHOOSE(IFERROR(MATCH(SMALL($O$13:$O$20,3),$O$13:$O$20,0),0),'Crédito 1'!$I$10,'Crédito 2'!$I$10,'Crédito 3'!$I$10,'Crédito 4'!$I$10,'Crédito 5'!$I$10,'Crédito 6'!$I$10,'Crédito 7'!$I$10,'Crédito 8'!$I$10)) | E27: =IF(B27="","",DAY(C27)) | F27: =IF(B27="","",IF(C27<Datos!$C$7,"Vencida",IF(C27-Datos!$C$7<=7,"Paga esta semana","Al día"))) | I27: Días 21 a 31 | K27: =SUMIFS($D$25:$D$32,$E$25:$E$32,">=21",$E$25:$E$32,"<=31") -> 0
B28: =IF(IFERROR(MATCH(SMALL($O$13:$O$20,4),$O$13:$O$20,0),0)=0,"",INDEX($B$13:$B$20,IFERROR(MATCH(SMALL($O$13:$O$20,4),$O$13:$O$20,0),0))) | C28: =IF(B28="","",CHOOSE(IFERROR(MATCH(SMALL($O$13:$O$20,4),$O$13:$O$20,0),0),'Crédito 1'!$I$9,'Crédito 2'!$I$9,'Crédito 3'!$I$9,'Crédito 4'!$I$9,'Crédito 5'!$I$9,'Crédito 6'!$I$9,'Crédito 7'!$I$9,'Crédito 8'!$I$9)) | D28: =IF(B28="","",CHOOSE(IFERROR(MATCH(SMALL($O$13:$O$20,4),$O$13:$O$20,0),0),'Crédito 1'!$I$10,'Crédito 2'!$I$10,'Crédito 3'!$I$10,'Crédito 4'!$I$10,'Crédito 5'!$I$10,'Crédito 6'!$I$10,'Crédito 7'!$I$10,'Crédito 8'!$I$10)) | E28: =IF(B28="","",DAY(C28)) | F28: =IF(B28="","",IF(C28<Datos!$C$7,"Vencida",IF(C28-Datos!$C$7<=7,"Paga esta semana","Al día"))) | I28: Total | K28: =SUM(K25:K27) -> 0
B29: =IF(IFERROR(MATCH(SMALL($O$13:$O$20,5),$O$13:$O$20,0),0)=0,"",INDEX($B$13:$B$20,IFERROR(MATCH(SMALL($O$13:$O$20,5),$O$13:$O$20,0),0))) | C29: =IF(B29="","",CHOOSE(IFERROR(MATCH(SMALL($O$13:$O$20,5),$O$13:$O$20,0),0),'Crédito 1'!$I$9,'Crédito 2'!$I$9,'Crédito 3'!$I$9,'Crédito 4'!$I$9,'Crédito 5'!$I$9,'Crédito 6'!$I$9,'Crédito 7'!$I$9,'Crédito 8'!$I$9)) | D29: =IF(B29="","",CHOOSE(IFERROR(MATCH(SMALL($O$13:$O$20,5),$O$13:$O$20,0),0),'Crédito 1'!$I$10,'Crédito 2'!$I$10,'Crédito 3'!$I$10,'Crédito 4'!$I$10,'Crédito 5'!$I$10,'Crédito 6'!$I$10,'Crédito 7'!$I$10,'Crédito 8'!$I$10)) | E29: =IF(B29="","",DAY(C29)) | F29: =IF(B29="","",IF(C29<Datos!$C$7,"Vencida",IF(C29-Datos!$C$7<=7,"Paga esta semana","Al día"))) | I29: Ten ese dinero en la cuenta antes de cada tramo.
B30: =IF(IFERROR(MATCH(SMALL($O$13:$O$20,6),$O$13:$O$20,0),0)=0,"",INDEX($B$13:$B$20,IFERROR(MATCH(SMALL($O$13:$O$20,6),$O$13:$O$20,0),0))) | C30: =IF(B30="","",CHOOSE(IFERROR(MATCH(SMALL($O$13:$O$20,6),$O$13:$O$20,0),0),'Crédito 1'!$I$9,'Crédito 2'!$I$9,'Crédito 3'!$I$9,'Crédito 4'!$I$9,'Crédito 5'!$I$9,'Crédito 6'!$I$9,'Crédito 7'!$I$9,'Crédito 8'!$I$9)) | D30: =IF(B30="","",CHOOSE(IFERROR(MATCH(SMALL($O$13:$O$20,6),$O$13:$O$20,0),0),'Crédito 1'!$I$10,'Crédito 2'!$I$10,'Crédito 3'!$I$10,'Crédito 4'!$I$10,'Crédito 5'!$I$10,'Crédito 6'!$I$10,'Crédito 7'!$I$10,'Crédito 8'!$I$10)) | E30: =IF(B30="","",DAY(C30)) | F30: =IF(B30="","",IF(C30<Datos!$C$7,"Vencida",IF(C30-Datos!$C$7<=7,"Paga esta semana","Al día")))
B31: =IF(IFERROR(MATCH(SMALL($O$13:$O$20,7),$O$13:$O$20,0),0)=0,"",INDEX($B$13:$B$20,IFERROR(MATCH(SMALL($O$13:$O$20,7),$O$13:$O$20,0),0))) | C31: =IF(B31="","",CHOOSE(IFERROR(MATCH(SMALL($O$13:$O$20,7),$O$13:$O$20,0),0),'Crédito 1'!$I$9,'Crédito 2'!$I$9,'Crédito 3'!$I$9,'Crédito 4'!$I$9,'Crédito 5'!$I$9,'Crédito 6'!$I$9,'Crédito 7'!$I$9,'Crédito 8'!$I$9)) | D31: =IF(B31="","",CHOOSE(IFERROR(MATCH(SMALL($O$13:$O$20,7),$O$13:$O$20,0),0),'Crédito 1'!$I$10,'Crédito 2'!$I$10,'Crédito 3'!$I$10,'Crédito 4'!$I$10,'Crédito 5'!$I$10,'Crédito 6'!$I$10,'Crédito 7'!$I$10,'Crédito 8'!$I$10)) | E31: =IF(B31="","",DAY(C31)) | F31: =IF(B31="","",IF(C31<Datos!$C$7,"Vencida",IF(C31-Datos!$C$7<=7,"Paga esta semana","Al día")))
B32: =IF(IFERROR(MATCH(SMALL($O$13:$O$20,8),$O$13:$O$20,0),0)=0,"",INDEX($B$13:$B$20,IFERROR(MATCH(SMALL($O$13:$O$20,8),$O$13:$O$20,0),0))) | C32: =IF(B32="","",CHOOSE(IFERROR(MATCH(SMALL($O$13:$O$20,8),$O$13:$O$20,0),0),'Crédito 1'!$I$9,'Crédito 2'!$I$9,'Crédito 3'!$I$9,'Crédito 4'!$I$9,'Crédito 5'!$I$9,'Crédito 6'!$I$9,'Crédito 7'!$I$9,'Crédito 8'!$I$9)) | D32: =IF(B32="","",CHOOSE(IFERROR(MATCH(SMALL($O$13:$O$20,8),$O$13:$O$20,0),0),'Crédito 1'!$I$10,'Crédito 2'!$I$10,'Crédito 3'!$I$10,'Crédito 4'!$I$10,'Crédito 5'!$I$10,'Crédito 6'!$I$10,'Crédito 7'!$I$10,'Crédito 8'!$I$10)) | E32: =IF(B32="","",DAY(C32)) | F32: =IF(B32="","",IF(C32<Datos!$C$7,"Vencida",IF(C32-Datos!$C$7<=7,"Paga esta semana","Al día")))
B33: Total del mes | D33: =SUM(D25:D32) -> 0
B35: 4. Plan de pago (hoja Plan de pago) | G35: Abono extra sugerido el próximo mes | I35: Valor
B36: Método | D36: ='Plan de pago'!$C$5 -> Avalancha | G36: =IF('Plan de pago'!$E$22=0,"",INDEX('Plan de pago'!$B$12:$B$19,'Plan de pago'!$E$22)) | I36: =IF(G36="","",'Plan de pago'!$G$28)
B37: Pago mensual total del plan | D37: ='Plan de pago'!$C$8 -> 0 | G37: =IF('Plan de pago'!$I$22=0,"",INDEX('Plan de pago'!$B$12:$B$19,'Plan de pago'!$I$22)) | I37: =IF(G37="","",'Plan de pago'!$K$28)
B38: Intereses y seguros solo con cuotas | D38: ='Plan de pago'!$O$20 -> 0 | G38: =IF('Plan de pago'!$M$22=0,"",INDEX('Plan de pago'!$B$12:$B$19,'Plan de pago'!$M$22)) | I38: =IF(G38="","",'Plan de pago'!$O$28)
B39: Intereses y seguros con el plan | D39: ='Plan de pago'!$P$20 -> 0 | G39: =IF('Plan de pago'!$Q$22=0,"",INDEX('Plan de pago'!$B$12:$B$19,'Plan de pago'!$Q$22)) | I39: =IF(G39="","",'Plan de pago'!$S$28)
B40: Ahorro con el plan | D40: ='Plan de pago'!$C$21 -> 0 | G40: =IF('Plan de pago'!$U$22=0,"",INDEX('Plan de pago'!$B$12:$B$19,'Plan de pago'!$U$22)) | I40: =IF(G40="","",'Plan de pago'!$W$28)
G41: =IF('Plan de pago'!$Y$22=0,"",INDEX('Plan de pago'!$B$12:$B$19,'Plan de pago'!$Y$22)) | I41: =IF(G41="","",'Plan de pago'!$AA$28)
G42: =IF('Plan de pago'!$AC$22=0,"",INDEX('Plan de pago'!$B$12:$B$19,'Plan de pago'!$AC$22)) | I42: =IF(G42="","",'Plan de pago'!$AE$28)
G43: =IF('Plan de pago'!$AG$22=0,"",INDEX('Plan de pago'!$B$12:$B$19,'Plan de pago'!$AG$22)) | I43: =IF(G43="","",'Plan de pago'!$AI$28)
G44: Si el valor es 0, este mes solo se pagan las cuotas normales.
B46: 5. Hitos: cuándo termina cada crédito y cuánto se libera (con las cuotas actuales)
B47: Crédito | C47: Termina | D47: Cuota que se libera | E47: Pago mensual después (cuotas completas) | F47: Años desde hoy | G47: Carga después
B48: =IF(IFERROR(MATCH(SMALL($N$60:$N$67,1),$N$60:$N$67,0),0)=0,"",INDEX($B$13:$B$20,IFERROR(MATCH(SMALL($N$60:$N$67,1),$N$60:$N$67,0),0))) | C48: =IF(B48="","",CHOOSE(IFERROR(MATCH(SMALL($N$60:$N$67,1),$N$60:$N$67,0),0),'Crédito 1'!$I$12,'Crédito 2'!$I$12,'Crédito 3'!$I$12,'Crédito 4'!$I$12,'Crédito 5'!$I$12,'Crédito 6'!$I$12,'Crédito 7'!$I$12,'Crédito 8'!$I$12)) | D48: =IF(B48="","",CHOOSE(IFERROR(MATCH(SMALL($N$60:$N$67,1),$N$60:$N$67,0),0),'Crédito 1'!$I$18,'Crédito 2'!$I$18,'Crédito 3'!$I$18,'Crédito 4'!$I$18,'Crédito 5'!$I$18,'Crédito 6'!$I$18,'Crédito 7'!$I$18,'Crédito 8'!$I$18)) | E48: =IF(B48="","",MAX(0,SUMIFS('Plan de pago'!$F$12:$F$19,'Plan de pago'!$C$12:$C$19,">0.5")-(D48))) | F48: =IF(B48="","",ROUND((C48-Datos!$C$7)/365.25,1)) | G48: =IF(OR(B48="",N(Datos!$F$16)=0),"",E48/Datos!$F$16)
...

Sheet Datos
B1: Datos generales, ingresos y carga financiera
B2: Celdas crema: datos que llenas. La fecha de corte por defecto es hoy.
B5: Cliente
B6: Asesor o marca
B7: Fecha de corte | C7: =TODAY() -> 46290 | D7: Define qué cuotas están vencidas.
B8: Tasa de cambio (pesos por dólar) | D8: La tasa que realmente te pagan.
B10: Ingreso | C10: Moneda | D10: Valor mensual en su moneda | E10: Meses al año que llega | F10: Promedio mensual en pesos | G10: Nota
C11: COP | E11: 12 | F11: =IF(N(D11)=0,0,IF(C11="USD",D11*N($C$8),D11)*N(E11)/12) -> 0
C12: COP | E12: 12 | F12: =IF(N(D12)=0,0,IF(C12="USD",D12*N($C$8),D12)*N(E12)/12) -> 0
C13: COP | E13: 12 | F13: =IF(N(D13)=0,0,IF(C13="USD",D13*N($C$8),D13)*N(E13)/12) -> 0
C14: COP | E14: 12 | F14: =IF(N(D14)=0,0,IF(C14="USD",D14*N($C$8),D14)*N(E14)/12) -> 0
C15: COP | E15: 12 | F15: =IF(N(D15)=0,0,IF(C15="USD",D15*N($C$8),D15)*N(E15)/12) -> 0
B16: Ingreso mensual promedio | F16: =SUM(F11:F15) -> 0
B17: De ese ingreso, dólares al mes (promedio) | F17: =SUMPRODUCT((C11:C15="USD")*D11:D15*E11:E15)/12 -> 0
B19: Gastos de vida al mes (sin deudas) | D19: Opcional. Mercado, servicios, transporte, etc.
B20: Pagos de deudas del próximo mes | C20: =Panel!$D$5 -> 0
B21: Carga financiera (deudas / ingreso) | C21: =IF(F16=0,"",C20/F16) | D21: =IF(C21="","",IF(C21<=0.3,"Sana (hasta 30%)",IF(C21<=0.4,"Alta (30% a 40%)",IF(C21<=0.5,"Muy alta (40% a 50%)","Crítica (más de 50%)"))))
B22: Disponible después de deudas y gastos | C22: =F16-C20-N(C19) -> 0
B24: Si la tasa de cambio fuera... (solo si hay ingresos en dólares)
B25: Tasa de cambio | C25: Ingreso mensual | D25: Carga financiera | E25: Disponible
B26: =IF(N($C$8)=0,"",$C$8*0.85) | C26: =IF(B26="","",$F$16+$F$17*(B26-$C$8)) | D26: =IF(OR(B26="",N(C26)=0),"",$C$20/C26) | E26: =IF(B26="","",C26-$C$20-N($C$19))
B27: =IF(N($C$8)=0,"",$C$8*0.9) | C27: =IF(B27="","",$F$16+$F$17*(B27-$C$8)) | D27: =IF(OR(B27="",N(C27)=0),"",$C$20/C27) | E27: =IF(B27="","",C27-$C$20-N($C$19))
B28: =IF(N($C$8)=0,"",$C$8*0.95) | C28: =IF(B28="","",$F$16+$F$17*(B28-$C$8)) | D28: =IF(OR(B28="",N(C28)=0),"",$C$20/C28) | E28: =IF(B28="","",C28-$C$20-N($C$19))
B29: =IF(N($C$8)=0,"",$C$8*1) | C29: =IF(B29="","",$F$16+$F$17*(B29-$C$8)) | D29: =IF(OR(B29="",N(C29)=0),"",$C$20/C29) | E29: =IF(B29="","",C29-$C$20-N($C$19))
B30: =IF(N($C$8)=0,"",$C$8*1.05) | C30: =IF(B30="","",$F$16+$F$17*(B30-$C$8)) | D30: =IF(OR(B30="",N(C30)=0),"",$C$20/C30) | E30: =IF(B30="","",C30-$C$20-N($C$19))
B31: =IF(N($C$8)=0,"",$C$8*1.1) | C31: =IF(B31="","",$F$16+$F$17*(B31-$C$8)) | D31: =IF(OR(B31="",N(C31)=0),"",$C$20/C31) | E31: =IF(B31="","",C31-$C$20-N($C$19))
B32: =IF(F17=0,"Sin ingresos en dólares: la tabla no aplica.","Cada 100 pesos que baje la tasa de cambio son "&ROUND(F17*100,0)&" pesos menos al mes.") -> Sin ingresos en dólares: la tabla no aplica.

Sheet Plan de pago
B1: Plan de pago: con plan frente a solo cuotas
B2: Con el plan, el pago total se mantiene: cuando un crédito termina, su cuota pasa como abono al siguiente de la lista.
B5: Método | C5: Avalancha | D5: Avalancha: mayor tasa primero. Bola de nieve: menor saldo primero. Orden manual: escribe el orden en la columna J.
B6: Dinero extra adicional al mes | C6: 0 | D6: 0 = el plan solo usa las cuotas que se liberan.
B7: Primer mes del plan | C7: =DATE(YEAR(Datos!$C$7),MONTH(Datos!$C$7)+1,1) -> 46296
B8: Pago mensual total del plan | C8: =SUMIFS(F12:F19,C12:C19,">0.5")+N(C6) -> 0
B11: Crédito | C11: Saldo actual | D11: Tasa EA | E11: Tasa mensual | F11: Cuota | G11: Seguros | H11: ¿Acepta abonos? | I11: Abonos desde | J11: Orden manual | K11: Orden | L11: Termina solo con cuotas | M11: Termina con el plan | N11: Meses antes | O11: Intereses y seguros solo con cuotas | P11: Intereses y seguros con el plan | Q11: clave | R11: fila
B12: =IF('Crédito 1'!$F$6="Sí",'Crédito 1'!$C$6,"") | C12: =IF(B12="",0,'Crédito 1'!$I$6) -> 0 | D12: =IF(B12="","",'Crédito 1'!$C$13) | E12: =IF(B12="",0,'Crédito 1'!$F$7) -> 0 | F12: =IF(B12="",0,'Crédito 1'!$F$9) -> 0 | G12: =IF(B12="",0,N('Crédito 1'!$C$15)) -> 0 | H12: =IF(B12="","",IF('Crédito 1'!$C$17="No","No","Sí")) | I12: =IF(B12="","",'Crédito 1'!$F$11) | K12: =IF(C12<=0.5,"",1+COUNTIFS($C$12:$C$19,">0.5",$Q$12:$Q$19,"<"&Q12)+COUNTIFS($C$12:$C$19,">0.5",$Q$12:$Q$19,Q12,$R$12:$R$19,"<"&R12)) | L12: =IF(C12<=0.5,"",IF(ISNUMBER(AK22),EDATE($C$7,AK22-1),AK22)) | M12: =IF(K12="","",IF(ISNUMBER(INDEX($E$22:$AJ$22,1,4*(K12-1)+3)),EDATE($C$7,INDEX($E$22:$AJ$22,1,4*(K12-1)+3)-1),INDEX($E$22:$AJ$22,1,4*(K12-1)+3))) | N12: =IF(OR(K12="",NOT(ISNUMBER(L12)),NOT(ISNUMBER(M12))),"",(YEAR(L12)-YEAR(M12))*12+MONTH(L12)-MONTH(M12)) | O12: =IF(C12<=0.5,0,AK23) -> 0 | P12: =IF(K12="",0,INDEX($E$22:$AJ$22,1,4*(K12-1)+4)) -> 0 | Q12: =IF($C$5="Avalancha",-N(D12),IF($C$5="Bola de nieve",C12,IF(N(J12)=0,1000+R12,J12))) -> 0 | R12: =ROW() -> 12
B13: =IF('Crédito 2'!$F$6="Sí",'Crédito 2'!$C$6,"") | C13: =IF(B13="",0,'Crédito 2'!$I$6) -> 0 | D13: =IF(B13="","",'Crédito 2'!$C$13) | E13: =IF(B13="",0,'Crédito 2'!$F$7) -> 0 | F13: =IF(B13="",0,'Crédito 2'!$F$9) -> 0 | G13: =IF(B13="",0,N('Crédito 2'!$C$15)) -> 0 | H13: =IF(B13="","",IF('Crédito 2'!$C$17="No","No","Sí")) | I13: =IF(B13="","",'Crédito 2'!$F$11) | K13: =IF(C13<=0.5,"",1+COUNTIFS($C$12:$C$19,">0.5",$Q$12:$Q$19,"<"&Q13)+COUNTIFS($C$12:$C$19,">0.5",$Q$12:$Q$19,Q13,$R$12:$R$19,"<"&R13)) | L13: =IF(C13<=0.5,"",IF(ISNUMBER(AL22),EDATE($C$7,AL22-1),AL22)) | M13: =IF(K13="","",IF(ISNUMBER(INDEX($E$22:$AJ$22,1,4*(K13-1)+3)),EDATE($C$7,INDEX($E$22:$AJ$22,1,4*(K13-1)+3)-1),INDEX($E$22:$AJ$22,1,4*(K13-1)+3))) | N13: =IF(OR(K13="",NOT(ISNUMBER(L13)),NOT(ISNUMBER(M13))),"",(YEAR(L13)-YEAR(M13))*12+MONTH(L13)-MONTH(M13)) | O13: =IF(C13<=0.5,0,AL23) -> 0 | P13: =IF(K13="",0,INDEX($E$22:$AJ$22,1,4*(K13-1)+4)) -> 0 | Q13: =IF($C$5="Avalancha",-N(D13),IF($C$5="Bola de nieve",C13,IF(N(J13)=0,1000+R13,J13))) -> 0 | R13: =ROW() -> 13
B14: =IF('Crédito 3'!$F$6="Sí",'Crédito 3'!$C$6,"") | C14: =IF(B14="",0,'Crédito 3'!$I$6) -> 0 | D14: =IF(B14="","",'Crédito 3'!$C$13) | E14: =IF(B14="",0,'Crédito 3'!$F$7) -> 0 | F14: =IF(B14="",0,'Crédito 3'!$F$9) -> 0 | G14: =IF(B14="",0,N('Crédito 3'!$C$15)) -> 0 | H14: =IF(B14="","",IF('Crédito 3'!$C$17="No","No","Sí")) | I14: =IF(B14="","",'Crédito 3'!$F$11) | K14: =IF(C14<=0.5,"",1+COUNTIFS($C$12:$C$19,">0.5",$Q$12:$Q$19,"<"&Q14)+COUNTIFS($C$12:$C$19,">0.5",$Q$12:$Q$19,Q14,$R$12:$R$19,"<"&R14)) | L14: =IF(C14<=0.5,"",IF(ISNUMBER(AM22),EDATE($C$7,AM22-1),AM22)) | M14: =IF(K14="","",IF(ISNUMBER(INDEX($E$22:$AJ$22,1,4*(K14-1)+3)),EDATE($C$7,INDEX($E$22:$AJ$22,1,4*(K14-1)+3)-1),INDEX($E$22:$AJ$22,1,4*(K14-1)+3))) | N14: =IF(OR(K14="",NOT(ISNUMBER(L14)),NOT(ISNUMBER(M14))),"",(YEAR(L14)-YEAR(M14))*12+MONTH(L14)-MONTH(M14)) | O14: =IF(C14<=0.5,0,AM23) -> 0 | P14: =IF(K14="",0,INDEX($E$22:$AJ$22,1,4*(K14-1)+4)) -> 0 | Q14: =IF($C$5="Avalancha",-N(D14),IF($C$5="Bola de nieve",C14,IF(N(J14)=0,1000+R14,J14))) -> 0 | R14: =ROW() -> 14
B15: =IF('Crédito 4'!$F$6="Sí",'Crédito 4'!$C$6,"") | C15: =IF(B15="",0,'Crédito 4'!$I$6) -> 0 | D15: =IF(B15="","",'Crédito 4'!$C$13) | E15: =IF(B15="",0,'Crédito 4'!$F$7) -> 0 | F15: =IF(B15="",0,'Crédito 4'!$F$9) -> 0 | G15: =IF(B15="",0,N('Crédito 4'!$C$15)) -> 0 | H15: =IF(B15="","",IF('Crédito 4'!$C$17="No","No","Sí")) | I15: =IF(B15="","",'Crédito 4'!$F$11) | K15: =IF(C15<=0.5,"",1+COUNTIFS($C$12:$C$19,">0.5",$Q$12:$Q$19,"<"&Q15)+COUNTIFS($C$12:$C$19,">0.5",$Q$12:$Q$19,Q15,$R$12:$R$19,"<"&R15)) | L15: =IF(C15<=0.5,"",IF(ISNUMBER(AN22),EDATE($C$7,AN22-1),AN22)) | M15: =IF(K15="","",IF(ISNUMBER(INDEX($E$22:$AJ$22,1,4*(K15-1)+3)),EDATE($C$7,INDEX($E$22:$AJ$22,1,4*(K15-1)+3)-1),INDEX($E$22:$AJ$22,1,4*(K15-1)+3))) | N15: =IF(OR(K15="",NOT(ISNUMBER(L15)),NOT(ISNUMBER(M15))),"",(YEAR(L15)-YEAR(M15))*12+MONTH(L15)-MONTH(M15)) | O15: =IF(C15<=0.5,0,AN23) -> 0 | P15: =IF(K15="",0,INDEX($E$22:$AJ$22,1,4*(K15-1)+4)) -> 0 | Q15: =IF($C$5="Avalancha",-N(D15),IF($C$5="Bola de nieve",C15,IF(N(J15)=0,1000+R15,J15))) -> 0 | R15: =ROW() -> 15
B16: =IF('Crédito 5'!$F$6="Sí",'Crédito 5'!$C$6,"") | C16: =IF(B16="",0,'Crédito 5'!$I$6) -> 0 | D16: =IF(B16="","",'Crédito 5'!$C$13) | E16: =IF(B16="",0,'Crédito 5'!$F$7) -> 0 | F16: =IF(B16="",0,'Crédito 5'!$F$9) -> 0 | G16: =IF(B16="",0,N('Crédito 5'!$C$15)) -> 0 | H16: =IF(B16="","",IF('Crédito 5'!$C$17="No","No","Sí")) | I16: =IF(B16="","",'Crédito 5'!$F$11) | K16: =IF(C16<=0.5,"",1+COUNTIFS($C$12:$C$19,">0.5",$Q$12:$Q$19,"<"&Q16)+COUNTIFS($C$12:$C$19,">0.5",$Q$12:$Q$19,Q16,$R$12:$R$19,"<"&R16)) | L16: =IF(C16<=0.5,"",IF(ISNUMBER(AO22),EDATE($C$7,AO22-1),AO22)) | M16: =IF(K16="","",IF(ISNUMBER(INDEX($E$22:$AJ$22,1,4*(K16-1)+3)),EDATE($C$7,INDEX($E$22:$AJ$22,1,4*(K16-1)+3)-1),INDEX($E$22:$AJ$22,1,4*(K16-1)+3))) | N16: =IF(OR(K16="",NOT(ISNUMBER(L16)),NOT(ISNUMBER(M16))),"",(YEAR(L16)-YEAR(M16))*12+MONTH(L16)-MONTH(M16)) | O16: =IF(C16<=0.5,0,AO23) -> 0 | P16: =IF(K16="",0,INDEX($E$22:$AJ$22,1,4*(K16-1)+4)) -> 0 | Q16: =IF($C$5="Avalancha",-N(D16),IF($C$5="Bola de nieve",C16,IF(N(J16)=0,1000+R16,J16))) -> 0 | R16: =ROW() -> 16
B17: =IF('Crédito 6'!$F$6="Sí",'Crédito 6'!$C$6,"") | C17: =IF(B17="",0,'Crédito 6'!$I$6) -> 0 | D17: =IF(B17="","",'Crédito 6'!$C$13) | E17: =IF(B17="",0,'Crédito 6'!$F$7) -> 0 | F17: =IF(B17="",0,'Crédito 6'!$F$9) -> 0 | G17: =IF(B17="",0,N('Crédito 6'!$C$15)) -> 0 | H17: =IF(B17="","",IF('Crédito 6'!$C$17="No","No","Sí")) | I17: =IF(B17="","",'Crédito 6'!$F$11) | K17: =IF(C17<=0.5,"",1+COUNTIFS($C$12:$C$19,">0.5",$Q$12:$Q$19,"<"&Q17)+COUNTIFS($C$12:$C$19,">0.5",$Q$12:$Q$19,Q17,$R$12:$R$19,"<"&R17)) | L17: =IF(C17<=0.5,"",IF(ISNUMBER(AP22),EDATE($C$7,AP22-1),AP22)) | M17: =IF(K17="","",IF(ISNUMBER(INDEX($E$22:$AJ$22,1,4*(K17-1)+3)),EDATE($C$7,INDEX($E$22:$AJ$22,1,4*(K17-1)+3)-1),INDEX($E$22:$AJ$22,1,4*(K17-1)+3))) | N17: =IF(OR(K17="",NOT(ISNUMBER(L17)),NOT(ISNUMBER(M17))),"",(YEAR(L17)-YEAR(M17))*12+MONTH(L17)-MONTH(M17)) | O17: =IF(C17<=0.5,0,AP23) -> 0 | P17: =IF(K17="",0,INDEX($E$22:$AJ$22,1,4*(K17-1)+4)) -> 0 | Q17: =IF($C$5="Avalancha",-N(D17),IF($C$5="Bola de nieve",C17,IF(N(J17)=0,1000+R17,J17))) -> 0 | R17: =ROW() -> 17
B18: =IF('Crédito 7'!$F$6="Sí",'Crédito 7'!$C$6,"") | C18: =IF(B18="",0,'Crédito 7'!$I$6) -> 0 | D18: =IF(B18="","",'Crédito 7'!$C$13) | E18: =IF(B18="",0,'Crédito 7'!$F$7) -> 0 | F18: =IF(B18="",0,'Crédito 7'!$F$9) -> 0 | G18: =IF(B18="",0,N('Crédito 7'!$C$15)) -> 0 | H18: =IF(B18="","",IF('Crédito 7'!$C$17="No","No","Sí")) | I18: =IF(B18="","",'Crédito 7'!$F$11) | K18: =IF(C18<=0.5,"",1+COUNTIFS($C$12:$C$19,">0.5",$Q$12:$Q$19,"<"&Q18)+COUNTIFS($C$12:$C$19,">0.5",$Q$12:$Q$19,Q18,$R$12:$R$19,"<"&R18)) | L18: =IF(C18<=0.5,"",IF(ISNUMBER(AQ22),EDATE($C$7,AQ22-1),AQ22)) | M18: =IF(K18="","",IF(ISNUMBER(INDEX($E$22:$AJ$22,1,4*(K18-1)+3)),EDATE($C$7,INDEX($E$22:$AJ$22,1,4*(K18-1)+3)-1),INDEX($E$22:$AJ$22,1,4*(K18-1)+3))) | N18: =IF(OR(K18="",NOT(ISNUMBER(L18)),NOT(ISNUMBER(M18))),"",(YEAR(L18)-YEAR(M18))*12+MONTH(L18)-MONTH(M18)) | O18: =IF(C18<=0.5,0,AQ23) -> 0 | P18: =IF(K18="",0,INDEX($E$22:$AJ$22,1,4*(K18-1)+4)) -> 0 | Q18: =IF($C$5="Avalancha",-N(D18),IF($C$5="Bola de nieve",C18,IF(N(J18)=0,1000+R18,J18))) -> 0 | R18: =ROW() -> 18
B19: =IF('Crédito 8'!$F$6="Sí",'Crédito 8'!$C$6,"") | C19: =IF(B19="",0,'Crédito 8'!$I$6) -> 0 | D19: =IF(B19="","",'Crédito 8'!$C$13) | E19: =IF(B19="",0,'Crédito 8'!$F$7) -> 0 | F19: =IF(B19="",0,'Crédito 8'!$F$9) -> 0 | G19: =IF(B19="",0,N('Crédito 8'!$C$15)) -> 0 | H19: =IF(B19="","",IF('Crédito 8'!$C$17="No","No","Sí")) | I19: =IF(B19="","",'Crédito 8'!$F$11) | K19: =IF(C19<=0.5,"",1+COUNTIFS($C$12:$C$19,">0.5",$Q$12:$Q$19,"<"&Q19)+COUNTIFS($C$12:$C$19,">0.5",$Q$12:$Q$19,Q19,$R$12:$R$19,"<"&R19)) | L19: =IF(C19<=0.5,"",IF(ISNUMBER(AR22),EDATE($C$7,AR22-1),AR22)) | M19: =IF(K19="","",IF(ISNUMBER(INDEX($E$22:$AJ$22,1,4*(K19-1)+3)),EDATE($C$7,INDEX($E$22:$AJ$22,1,4*(K19-1)+3)-1),INDEX($E$22:$AJ$22,1,4*(K19-1)+3))) | N19: =IF(OR(K19="",NOT(ISNUMBER(L19)),NOT(ISNUMBER(M19))),"",(YEAR(L19)-YEAR(M19))*12+MONTH(L19)-MONTH(M19)) | O19: =IF(C19<=0.5,0,AR23) -> 0 | P19: =IF(K19="",0,INDEX($E$22:$AJ$22,1,4*(K19-1)+4)) -> 0 | Q19: =IF($C$5="Avalancha",-N(D19),IF($C$5="Bola de nieve",C19,IF(N(J19)=0,1000+R19,J19))) -> 0 | R19: =ROW() -> 19
B20: Total | C20: =SUM(C12:C19) -> 0 | F20: =SUM(F12:F19) -> 0 | O20: =SUM(O12:O19) -> 0 | P20: =SUM(P12:P19) -> 0
B21: Ahorro en intereses con el plan | C21: =O20-P20 -> 0 | E21: El FRECH no cambia el plan: el gobierno paga parte de la cuota y el saldo baja igual.
E22: =IFERROR(MATCH(1,$K$12:$K$19,0),0) -> 0 | F22: =IF(E22=0,"(vacío)","Orden 1: "&INDEX($B$12:$B$19,E22)) -> (vacío) | G22: =IF(F25<=0.5,0,IF(H387>0.5,"Más de 360",COUNTIF(H28:H387,">0.5")+1)) -> 0 | H22: =IF(F25<=0.5,0,SUM(F28:F387)+SUM(G28:G387)+H387-F25) -> 0 | I22: =IFERROR(MATCH(2,$K$12:$K$19,0),0) -> 0 | J22: =IF(I22=0,"(vacío)","Orden 2: "&INDEX($B$12:$B$19,I22)) -> (vacío) | K22: =IF(J25<=0.5,0,IF(L387>0.5,"Más de 360",COUNTIF(L28:L387,">0.5")+1)) -> 0 | L22: =IF(J25<=0.5,0,SUM(J28:J387)+SUM(K28:K387)+L387-J25) -> 0 | M22: =IFERROR(MATCH(3,$K$12:$K$19,0),0) -> 0 | N22: =IF(M22=0,"(vacío)","Orden 3: "&INDEX($B$12:$B$19,M22)) -> (vacío) | O22: =IF(N25<=0.5,0,IF(P387>0.5,"Más de 360",COUNTIF(P28:P387,">0.5")+1)) -> 0 | P22: =IF(N25<=0.5,0,SUM(N28:N387)+SUM(O28:O387)+P387-N25) -> 0 | Q22: =IFERROR(MATCH(4,$K$12:$K$19,0),0) -> 0 | R22: =IF(Q22=0,"(vacío)","Orden 4: "&INDEX($B$12:$B$19,Q22)) -> (vacío) | S22: =IF(R25<=0.5,0,IF(T387>0.5,"Más de 360",COUNTIF(T28:T387,">0.5")+1)) -> 0 | T22: =IF(R25<=0.5,0,SUM(R28:R387)+SUM(S28:S387)+T387-R25) -> 0 | U22: =IFERROR(MATCH(5,$K$12:$K$19,0),0) -> 0 | V22: =IF(U22=0,"(vacío)","Orden 5: "&INDEX($B$12:$B$19,U22)) -> (vacío) | W22: =IF(V25<=0.5,0,IF(X387>0.5,"Más de 360",COUNTIF(X28:X387,">0.5")+1)) -> 0 | X22: =IF(V25<=0.5,0,SUM(V28:V387)+SUM(W28:W387)+X387-V25) -> 0 | Y22: =IFERROR(MATCH(6,$K$12:$K$19,0),0) -> 0 | Z22: =IF(Y22=0,"(vacío)","Orden 6: "&INDEX($B$12:$B$19,Y22)) -> (vacío) | AA22: =IF(Z25<=0.5,0,IF(AB387>0.5,"Más de 360",COUNTIF(AB28:AB387,">0.5")+1)) -> 0 | AB22: =IF(Z25<=0.5,0,SUM(Z28:Z387)+SUM(AA28:AA387)+AB387-Z25) -> 0 | AC22: =IFERROR(MATCH(7,$K$12:$K$19,0),0) -> 0 | AD22: =IF(AC22=0,"(vacío)","Orden 7: "&INDEX($B$12:$B$19,AC22)) -> (vacío) | AE22: =IF(AD25<=0.5,0,IF(AF387>0.5,"Más de 360",COUNTIF(AF28:AF387,">0.5")+1)) -> 0 | AF22: =IF(AD25<=0.5,0,SUM(AD28:AD387)+SUM(AE28:AE387)+AF387-AD25) -> 0 | AG22: =IFERROR(MATCH(8,$K$12:$K$19,0),0) -> 0 | AH22: =IF(AG22=0,"(vacío)","Orden 8: "&INDEX($B$12:$B$19,AG22)) -> (vacío) | AI22: =IF(AH25<=0.5,0,IF(AJ387>0.5,"Más de 360",COUNTIF(AJ28:AJ387,">0.5")+1)) -> 0 | AJ22: =IF(AH25<=0.5,0,SUM(AH28:AH387)+SUM(AI28:AI387)+AJ387-AH25) -> 0 | AK22: =IF($C$12<=0.5,0,IF(AK387>0.5,"Más de 360",COUNTIF(AK28:AK387,">0.5")+1)) -> 0 | AL22: =IF($C$13<=0.5,0,IF(AL387>0.5,"Más de 360",COUNTIF(AL28:AL387,">0.5")+1)) -> 0 | AM22: =IF($C$14<=0.5,0,IF(AM387>0.5,"Más de 360",COUNTIF(AM28:AM387,">0.5")+1)) -> 0 | AN22: =IF($C$15<=0.5,0,IF(AN387>0.5,"Más de 360",COUNTIF(AN28:AN387,">0.5")+1)) -> 0 | AO22: =IF($C$16<=0.5,0,IF(AO387>0.5,"Más de 360",COUNTIF(AO28:AO387,">0.5")+1)) -> 0 | AP22: =IF($C$17<=0.5,0,IF(AP387>0.5,"Más de 360",COUNTIF(AP28:AP387,">0.5")+1)) -> 0 | AQ22: =IF($C$18<=0.5,0,IF(AQ387>0.5,"Más de 360",COUNTIF(AQ28:AQ387,">0.5")+1)) -> 0 | AR22: =IF($C$19<=0.5,0,IF(AR387>0.5,"Más de 360",COUNTIF(AR28:AR387,">0.5")+1)) -> 0
B23: Motor del plan (mes a mes) | E23: =IF(E22=0,0,INDEX($E$12:$E$19,E22)) -> 0 | F23: =IF(E22=0,0,INDEX($F$12:$F$19,E22)) -> 0 | I23: =IF(I22=0,0,INDEX($E$12:$E$19,I22)) -> 0 | J23: =IF(I22=0,0,INDEX($F$12:$F$19,I22)) -> 0 | M23: =IF(M22=0,0,INDEX($E$12:$E$19,M22)) -> 0 | N23: =IF(M22=0,0,INDEX($F$12:$F$19,M22)) -> 0 | Q23: =IF(Q22=0,0,INDEX($E$12:$E$19,Q22)) -> 0 | R23: =IF(Q22=0,0,INDEX($F$12:$F$19,Q22)) -> 0 | U23: =IF(U22=0,0,INDEX($E$12:$E$19,U22)) -> 0 | V23: =IF(U22=0,0,INDEX($F$12:$F$19,U22)) -> 0 | Y23: =IF(Y22=0,0,INDEX($E$12:$E$19,Y22)) -> 0 | Z23: =IF(Y22=0,0,INDEX($F$12:$F$19,Y22)) -> 0 | AC23: =IF(AC22=0,0,INDEX($E$12:$E$19,AC22)) -> 0 | AD23: =IF(AC22=0,0,INDEX($F$12:$F$19,AC22)) -> 0 | AG23: =IF(AG22=0,0,INDEX($E$12:$E$19,AG22)) -> 0 | AH23: =IF(AG22=0,0,INDEX($F$12:$F$19,AG22)) -> 0 | AK23: =IF($C$12<=0.5,0,$E$12*($C$12+SUM(AK28:AK386))+$G$12*(1+COUNTIF(AK28:AK386,">0.5"))) -> 0 | AL23: =IF($C$13<=0.5,0,$E$13*($C$13+SUM(AL28:AL386))+$G$13*(1+COUNTIF(AL28:AL386,">0.5"))) -> 0 | AM23: =IF($C$14<=0.5,0,$E$14*($C$14+SUM(AM28:AM386))+$G$14*(1+COUNTIF(AM28:AM386,">0.5"))) -> 0 | AN23: =IF($C$15<=0.5,0,$E$15*($C$15+SUM(AN28:AN386))+$G$15*(1+COUNTIF(AN28:AN386,">0.5"))) -> 0 | AO23: =IF($C$16<=0.5,0,$E$16*($C$16+SUM(AO28:AO386))+$G$16*(1+COUNTIF(AO28:AO386,">0.5"))) -> 0 | AP23: =IF($C$17<=0.5,0,$E$17*($C$17+SUM(AP28:AP386))+$G$17*(1+COUNTIF(AP28:AP386,">0.5"))) -> 0 | AQ23: =IF($C$18<=0.5,0,$E$18*($C$18+SUM(AQ28:AQ386))+$G$18*(1+COUNTIF(AQ28:AQ386,">0.5"))) -> 0 | AR23: =IF($C$19<=0.5,0,$E$19*($C$19+SUM(AR28:AR386))+$G$19*(1+COUNTIF(AR28:AR386,">0.5"))) -> 0
E24: =IF(E22=0,0,INDEX($G$12:$G$19,E22)) -> 0 | F24: =IF(E22=0,0,IF(INDEX($H$12:$H$19,E22)="No",0,1)) -> 0 | I24: =IF(I22=0,0,INDEX($G$12:$G$19,I22)) -> 0 | J24: =IF(I22=0,0,IF(INDEX($H$12:$H$19,I22)="No",0,1)) -> 0 | M24: =IF(M22=0,0,INDEX($G$12:$G$19,M22)) -> 0 | N24: =IF(M22=0,0,IF(INDEX($H$12:$H$19,M22)="No",0,1)) -> 0 | Q24: =IF(Q22=0,0,INDEX($G$12:$G$19,Q22)) -> 0 | R24: =IF(Q22=0,0,IF(INDEX($H$12:$H$19,Q22)="No",0,1)) -> 0 | U24: =IF(U22=0,0,INDEX($G$12:$G$19,U22)) -> 0 | V24: =IF(U22=0,0,IF(INDEX($H$12:$H$19,U22)="No",0,1)) -> 0 | Y24: =IF(Y22=0,0,INDEX($G$12:$G$19,Y22)) -> 0 | Z24: =IF(Y22=0,0,IF(INDEX($H$12:$H$19,Y22)="No",0,1)) -> 0 | AC24: =IF(AC22=0,0,INDEX($G$12:$G$19,AC22)) -> 0 | AD24: =IF(AC22=0,0,IF(INDEX($H$12:$H$19,AC22)="No",0,1)) -> 0 | AG24: =IF(AG22=0,0,INDEX($G$12:$G$19,AG22)) -> 0 | AH24: =IF(AG22=0,0,IF(INDEX($H$12:$H$19,AG22)="No",0,1)) -> 0
E25: =IF(E22=0,"",IF(N(INDEX($I$12:$I$19,E22))=0,"",INDEX($I$12:$I$19,E22))) | F25: =IF(E22=0,0,INDEX($C$12:$C$19,E22)) -> 0 | I25: =IF(I22=0,"",IF(N(INDEX($I$12:$I$19,I22))=0,"",INDEX($I$12:$I$19,I22))) | J25: =IF(I22=0,0,INDEX($C$12:$C$19,I22)) -> 0 | M25: =IF(M22=0,"",IF(N(INDEX($I$12:$I$19,M22))=0,"",INDEX($I$12:$I$19,M22))) | N25: =IF(M22=0,0,INDEX($C$12:$C$19,M22)) -> 0 | Q25: =IF(Q22=0,"",IF(N(INDEX($I$12:$I$19,Q22))=0,"",INDEX($I$12:$I$19,Q22))) | R25: =IF(Q22=0,0,INDEX($C$12:$C$19,Q22)) -> 0 | U25: =IF(U22=0,"",IF(N(INDEX($I$12:$I$19,U22))=0,"",INDEX($I$12:$I$19,U22))) | V25: =IF(U22=0,0,INDEX($C$12:$C$19,U22)) -> 0 | Y25: =IF(Y22=0,"",IF(N(INDEX($I$12:$I$19,Y22))=0,"",INDEX($I$12:$I$19,Y22))) | Z25: =IF(Y22=0,0,INDEX($C$12:$C$19,Y22)) -> 0 | AC25: =IF(AC22=0,"",IF(N(INDEX($I$12:$I$19,AC22))=0,"",INDEX($I$12:$I$19,AC22))) | AD25: =IF(AC22=0,0,INDEX($C$12:$C$19,AC22)) -> 0 | AG25: =IF(AG22=0,"",IF(N(INDEX($I$12:$I$19,AG22))=0,"",INDEX($I$12:$I$19,AG22))) | AH25: =IF(AG22=0,0,INDEX($C$12:$C$19,AG22)) -> 0
B26: Mes | C26: Fecha | D26: Disponible para extra | E26: Debe | F26: Cuota | G26: Extra | H26: Saldo | I26: Debe | J26: Cuota | K26: Extra | L26: Saldo | M26: Debe | N26: Cuota | O26: Extra | P26: Saldo | Q26: Debe | R26: Cuota | S26: Extra | T26: Saldo | U26: Debe | V26: Cuota | W26: Extra | X26: Saldo | Y26: Debe | Z26: Cuota | AA26: Extra | AB26: Saldo | AC26: Debe | AD26: Cuota | AE26: Extra | AF26: Saldo | AG26: Debe | AH26: Cuota | AI26: Extra | AJ26: Saldo | AK26: Solo cuotas 1 | AL26: Solo cuotas 2 | AM26: Solo cuotas 3 | AN26: Solo cuotas 4 | AO26: Solo cuotas 5 | AP26: Solo cuotas 6 | AQ26: Solo cuotas 7 | AR26: Solo cuotas 8 | AS26: Deuda con el plan | AT26: Deuda solo con cuotas | AU26: Pago del mes con el plan
B28: 1 | C28: =EDATE($C$7,0) -> 46296 | D28: =$C$8-(F28+J28+N28+R28+V28+Z28+AD28+AH28) -> 0 | E28: =IF(F$25>0.5,F$25*(1+E$23)+E$24,0) -> 0 | F28: =MIN(F$23,E28) -> 0 | G28: =IF(AND(F$24=1,OR(E$25="",$C28>=E$25)),MAX(0,MIN(E28-F28,$D28-(0))),0) -> 0 | H28: =E28-F28-G28 -> 0 | I28: =IF(J$25>0.5,J$25*(1+I$23)+I$24,0) -> 0 | J28: =MIN(J$23,I28) -> 0 | K28: =IF(AND(J$24=1,OR(I$25="",$C28>=I$25)),MAX(0,MIN(I28-J28,$D28-(G28))),0) -> 0 | L28: =I28-J28-K28 -> 0 | M28: =IF(N$25>0.5,N$25*(1+M$23)+M$24,0) -> 0 | N28: =MIN(N$23,M28) -> 0 | O28: =IF(AND(N$24=1,OR(M$25="",$C28>=M$25)),MAX(0,MIN(M28-N28,$D28-(G28+K28))),0) -> 0 | P28: =M28-N28-O28 -> 0 | Q28: =IF(R$25>0.5,R$25*(1+Q$23)+Q$24,0) -> 0 | R28: =MIN(R$23,Q28) -> 0 | S28: =IF(AND(R$24=1,OR(Q$25="",$C28>=Q$25)),MAX(0,MIN(Q28-R28,$D28-(G28+K28+O28))),0) -> 0 | T28: =Q28-R28-S28 -> 0 | U28: =IF(V$25>0.5,V$25*(1+U$23)+U$24,0) -> 0 | V28: =MIN(V$23,U28) -> 0 | W28: =IF(AND(V$24=1,OR(U$25="",$C28>=U$25)),MAX(0,MIN(U28-V28,$D28-(G28+K28+O28+S28))),0) -> 0 | X28: =U28-V28-W28 -> 0 | Y28: =IF(Z$25>0.5,Z$25*(1+Y$23)+Y$24,0) -> 0 | Z28: =MIN(Z$23,Y28) -> 0 | AA28: =IF(AND(Z$24=1,OR(Y$25="",$C28>=Y$25)),MAX(0,MIN(Y28-Z28,$D28-(G28+K28+O28+S28+W28))),0) -> 0 | AB28: =Y28-Z28-AA28 -> 0 | AC28: =IF(AD$25>0.5,AD$25*(1+AC$23)+AC$24,0) -> 0 | AD28: =MIN(AD$23,AC28) -> 0 | AE28: =IF(AND(AD$24=1,OR(AC$25="",$C28>=AC$25)),MAX(0,MIN(AC28-AD28,$D28-(G28+K28+O28+S28+W28+AA28))),0) -> 0 | AF28: =AC28-AD28-AE28 -> 0 | AG28: =IF(AH$25>0.5,AH$25*(1+AG$23)+AG$24,0) -> 0 | AH28: =MIN(AH$23,AG28) -> 0 | AI28: =IF(AND(AH$24=1,OR(AG$25="",$C28>=AG$25)),MAX(0,MIN(AG28-AH28,$D28-(G28+K28+O28+S28+W28+AA28+AE28))),0) -> 0 | AJ28: =AG28-AH28-AI28 -> 0 | AK28: =IF($C$12>0.5,$C$12*(1+$E$12)+$G$12-MIN($F$12,$C$12*(1+$E$12)+$G$12),0) -> 0 | AL28: =IF($C$13>0.5,$C$13*(1+$E$13)+$G$13-MIN($F$13,$C$13*(1+$E$13)+$G$13),0) -> 0 | AM28: =IF($C$14>0.5,$C$14*(1+$E$14)+$G$14-MIN($F$14,$C$14*(1+$E$14)+$G$14),0) -> 0 | AN28: =IF($C$15>0.5,$C$15*(1+$E$15)+$G$15-MIN($F$15,$C$15*(1+$E$15)+$G$15),0) -> 0 | AO28: =IF($C$16>0.5,$C$16*(1+$E$16)+$G$16-MIN($F$16,$C$16*(1+$E$16)+$G$16),0) -> 0 | AP28: =IF($C$17>0.5,$C$17*(1+$E$17)+$G$17-MIN($F$17,$C$17*(1+$E$17)+$G$17),0) -> 0 | AQ28: =IF($C$18>0.5,$C$18*(1+$E$18)+$G$18-MIN($F$18,$C$18*(1+$E$18)+$G$18),0) -> 0 | AR28: =IF($C$19>0.5,$C$19*(1+$E$19)+$G$19-MIN($F$19,$C$19*(1+$E$19)+$G$19),0) -> 0 | AS28: =H28+L28+P28+T28+X28+AB28+AF28+AJ28 -> 0 | AT28: =SUM(AK28:AR28) -> 0 | AU28: =F28+G28+J28+K28+N28+O28+R28+S28+V28+W28+Z28+AA28+AD28+AE28+AH28+AI28 -> 0
B29: 2 | C29: =EDATE($C$7,1) -> 46327 | D29: =$C$8-(F29+J29+N29+R29+V29+Z29+AD29+AH29) -> 0 | E29: =IF(H28>0.5,H28*(1+E$23)+E$24,0) -> 0 | F29: =MIN(F$23,E29) -> 0 | G29: =IF(AND(F$24=1,OR(E$25="",$C29>=E$25)),MAX(0,MIN(E29-F29,$D29-(0))),0) -> 0 | H29: =E29-F29-G29 -> 0 | I29: =IF(L28>0.5,L28*(1+I$23)+I$24,0) -> 0 | J29: =MIN(J$23,I29) -> 0 | K29: =IF(AND(J$24=1,OR(I$25="",$C29>=I$25)),MAX(0,MIN(I29-J29,$D29-(G29))),0) -> 0 | L29: =I29-J29-K29 -> 0 | M29: =IF(P28>0.5,P28*(1+M$23)+M$24,0) -> 0 | N29: =MIN(N$23,M29) -> 0 | O29: =IF(AND(N$24=1,OR(M$25="",$C29>=M$25)),MAX(0,MIN(M29-N29,$D29-(G29+K29))),0) -> 0 | P29: =M29-N29-O29 -> 0 | Q29: =IF(T28>0.5,T28*(1+Q$23)+Q$24,0) -> 0 | R29: =MIN(R$23,Q29) -> 0 | S29: =IF(AND(R$24=1,OR(Q$25="",$C29>=Q$25)),MAX(0,MIN(Q29-R29,$D29-(G29+K29+O29))),0) -> 0 | T29: =Q29-R29-S29 -> 0 | U29: =IF(X28>0.5,X28*(1+U$23)+U$24,0) -> 0 | V29: =MIN(V$23,U29) -> 0 | W29: =IF(AND(V$24=1,OR(U$25="",$C29>=U$25)),MAX(0,MIN(U29-V29,$D29-(G29+K29+O29+S29))),0) -> 0 | X29: =U29-V29-W29 -> 0 | Y29: =IF(AB28>0.5,AB28*(1+Y$23)+Y$24,0) -> 0 | Z29: =MIN(Z$23,Y29) -> 0 | AA29: =IF(AND(Z$24=1,OR(Y$25="",$C29>=Y$25)),MAX(0,MIN(Y29-Z29,$D29-(G29+K29+O29+S29+W29))),0) -> 0 | AB29: =Y29-Z29-AA29 -> 0 | AC29: =IF(AF28>0.5,AF28*(1+AC$23)+AC$24,0) -> 0 | AD29: =MIN(AD$23,AC29) -> 0 | AE29: =IF(AND(AD$24=1,OR(AC$25="",$C29>=AC$25)),MAX(0,MIN(AC29-AD29,$D29-(G29+K29+O29+S29+W29+AA29))),0) -> 0 | AF29: =AC29-AD29-AE29 -> 0 | AG29: =IF(AJ28>0.5,AJ28*(1+AG$23)+AG$24,0) -> 0 | AH29: =MIN(AH$23,AG29) -> 0 | AI29: =IF(AND(AH$24=1,OR(AG$25="",$C29>=AG$25)),MAX(0,MIN(AG29-AH29,$D29-(G29+K29+O29+S29+W29+AA29+AE29))),0) -> 0 | AJ29: =AG29-AH29-AI29 -> 0 | AK29: =IF(AK28>0.5,AK28*(1+$E$12)+$G$12-MIN($F$12,AK28*(1+$E$12)+$G$12),0) -> 0 | AL29: =IF(AL28>0.5,AL28*(1+$E$13)+$G$13-MIN($F$13,AL28*(1+$E$13)+$G$13),0) -> 0 | AM29: =IF(AM28>0.5,AM28*(1+$E$14)+$G$14-MIN($F$14,AM28*(1+$E$14)+$G$14),0) -> 0 | AN29: =IF(AN28>0.5,AN28*(1+$E$15)+$G$15-MIN($F$15,AN28*(1+$E$15)+$G$15),0) -> 0 | AO29: =IF(AO28>0.5,AO28*(1+$E$16)+$G$16-MIN($F$16,AO28*(1+$E$16)+$G$16),0) -> 0 | AP29: =IF(AP28>0.5,AP28*(1+$E$17)+$G$17-MIN($F$17,AP28*(1+$E$17)+$G$17),0) -> 0 | AQ29: =IF(AQ28>0.5,AQ28*(1+$E$18)+$G$18-MIN($F$18,AQ28*(1+$E$18)+$G$18),0) -> 0 | AR29: =IF(AR28>0.5,AR28*(1+$E$19)+$G$19-MIN($F$19,AR28*(1+$E$19)+$G$19),0) -> 0 | AS29: =H29+L29+P29+T29+X29+AB29+AF29+AJ29 -> 0 | AT29: =SUM(AK29:AR29) -> 0 | AU29: =F29+G29+J29+K29+N29+O29+R29+S29+V29+W29+Z29+AA29+AD29+AE29+AH29+AI29 -> 0
B30: 3 | C30: =EDATE($C$7,2) -> 46357 | D30: =$C$8-(F30+J30+N30+R30+V30+Z30+AD30+AH30) -> 0 | E30: =IF(H29>0.5,H29*(1+E$23)+E$24,0) -> 0 | F30: =MIN(F$23,E30) -> 0 | G30: =IF(AND(F$24=1,OR(E$25="",$C30>=E$25)),MAX(0,MIN(E30-F30,$D30-(0))),0) -> 0 | H30: =E30-F30-G30 -> 0 | I30: =IF(L29>0.5,L29*(1+I$23)+I$24,0) -> 0 | J30: =MIN(J$23,I30) -> 0 | K30: =IF(AND(J$24=1,OR(I$25="",$C30>=I$25)),MAX(0,MIN(I30-J30,$D30-(G30))),0) -> 0 | L30: =I30-J30-K30 -> 0 | M30: =IF(P29>0.5,P29*(1+M$23)+M$24,0) -> 0 | N30: =MIN(N$23,M30) -> 0 | O30: =IF(AND(N$24=1,OR(M$25="",$C30>=M$25)),MAX(0,MIN(M30-N30,$D30-(G30+K30))),0) -> 0 | P30: =M30-N30-O30 -> 0 | Q30: =IF(T29>0.5,T29*(1+Q$23)+Q$24,0) -> 0 | R30: =MIN(R$23,Q30) -> 0 | S30: =IF(AND(R$24=1,OR(Q$25="",$C30>=Q$25)),MAX(0,MIN(Q30-R30,$D30-(G30+K30+O30))),0) -> 0 | T30: =Q30-R30-S30 -> 0 | U30: =IF(X29>0.5,X29*(1+U$23)+U$24,0) -> 0 | V30: =MIN(V$23,U30) -> 0 | W30: =IF(AND(V$24=1,OR(U$25="",$C30>=U$25)),MAX(0,MIN(U30-V30,$D30-(G30+K30+O30+S30))),0) -> 0 | X30: =U30-V30-W30 -> 0 | Y30: =IF(AB29>0.5,AB29*(1+Y$23)+Y$24,0) -> 0 | Z30: =MIN(Z$23,Y30) -> 0 | AA30: =IF(AND(Z$24=1,OR(Y$25="",$C30>=Y$25)),MAX(0,MIN(Y30-Z30,$D30-(G30+K30+O30+S30+W30))),0) -> 0 | AB30: =Y30-Z30-AA30 -> 0 | AC30: =IF(AF29>0.5,AF29*(1+AC$23)+AC$24,0) -> 0 | AD30: =MIN(AD$23,AC30) -> 0 | AE30: =IF(AND(AD$24=1,OR(AC$25="",$C30>=AC$25)),MAX(0,MIN(AC30-AD30,$D30-(G30+K30+O30+S30+W30+AA30))),0) -> 0 | AF30: =AC30-AD30-AE30 -> 0 | AG30: =IF(AJ29>0.5,AJ29*(1+AG$23)+AG$24,0) -> 0 | AH30: =MIN(AH$23,AG30) -> 0 | AI30: =IF(AND(AH$24=1,OR(AG$25="",$C30>=AG$25)),MAX(0,MIN(AG30-AH30,$D30-(G30+K30+O30+S30+W30+AA30+AE30))),0) -> 0 | AJ30: =AG30-AH30-AI30 -> 0 | AK30: =IF(AK29>0.5,AK29*(1+$E$12)+$G$12-MIN($F$12,AK29*(1+$E$12)+$G$12),0) -> 0 | AL30: =IF(AL29>0.5,AL29*(1+$E$13)+$G$13-MIN($F$13,AL29*(1+$E$13)+$G$13),0) -> 0 | AM30: =IF(AM29>0.5,AM29*(1+$E$14)+$G$14-MIN($F$14,AM29*(1+$E$14)+$G$14),0) -> 0 | AN30: =IF(AN29>0.5,AN29*(1+$E$15)+$G$15-MIN($F$15,AN29*(1+$E$15)+$G$15),0) -> 0 | AO30: =IF(AO29>0.5,AO29*(1+$E$16)+$G$16-MIN($F$16,AO29*(1+$E$16)+$G$16),0) -> 0 | AP30: =IF(AP29>0.5,AP29*(1+$E$17)+$G$17-MIN($F$17,AP29*(1+$E$17)+$G$17),0) -> 0 | AQ30: =IF(AQ29>0.5,AQ29*(1+$E$18)+$G$18-MIN($F$18,AQ29*(1+$E$18)+$G$18),0) -> 0 | AR30: =IF(AR29>0.5,AR29*(1+$E$19)+$G$19-MIN($F$19,AR29*(1+$E$19)+$G$19),0) -> 0 | AS30: =H30+L30+P30+T30+X30+AB30+AF30+AJ30 -> 0 | AT30: =SUM(AK30:AR30) -> 0 | AU30: =F30+G30+J30+K30+N30+O30+R30+S30+V30+W30+Z30+AA30+AD30+AE30+AH30+AI30 -> 0
B31: 4 | C31: =EDATE($C$7,3) -> 46388 | D31: =$C$8-(F31+J31+N31+R31+V31+Z31+AD31+AH31) -> 0 | E31: =IF(H30>0.5,H30*(1+E$23)+E$24,0) -> 0 | F31: =MIN(F$23,E31) -> 0 | G31: =IF(AND(F$24=1,OR(E$25="",$C31>=E$25)),MAX(0,MIN(E31-F31,$D31-(0))),0) -> 0 | H31: =E31-F31-G31 -> 0 | I31: =IF(L30>0.5,L30*(1+I$23)+I$24,0) -> 0 | J31: =MIN(J$23,I31) -> 0 | K31: =IF(AND(J$24=1,OR(I$25="",$C31>=I$25)),MAX(0,MIN(I31-J31,$D31-(G31))),0) -> 0 | L31: =I31-J31-K31 -> 0 | M31: =IF(P30>0.5,P30*(1+M$23)+M$24,0) -> 0 | N31: =MIN(N$23,M31) -> 0 | O31: =IF(AND(N$24=1,OR(M$25="",$C31>=M$25)),MAX(0,MIN(M31-N31,$D31-(G31+K31))),0) -> 0 | P31: =M31-N31-O31 -> 0 | Q31: =IF(T30>0.5,T30*(1+Q$23)+Q$24,0) -> 0 | R31: =MIN(R$23,Q31) -> 0 | S31: =IF(AND(R$24=1,OR(Q$25="",$C31>=Q$25)),MAX(0,MIN(Q31-R31,$D31-(G31+K31+O31))),0) -> 0 | T31: =Q31-R31-S31 -> 0 | U31: =IF(X30>0.5,X30*(1+U$23)+U$24,0) -> 0 | V31: =MIN(V$23,U31) -> 0 | W31: =IF(AND(V$24=1,OR(U$25="",$C31>=U$25)),MAX(0,MIN(U31-V31,$D31-(G31+K31+O31+S31))),0) -> 0 | X31: =U31-V31-W31 -> 0 | Y31: =IF(AB30>0.5,AB30*(1+Y$23)+Y$24,0) -> 0 | Z31: =MIN(Z$23,Y31) -> 0 | AA31: =IF(AND(Z$24=1,OR(Y$25="",$C31>=Y$25)),MAX(0,MIN(Y31-Z31,$D31-(G31+K31+O31+S31+W31))),0) -> 0 | AB31: =Y31-Z31-AA31 -> 0 | AC31: =IF(AF30>0.5,AF30*(1+AC$23)+AC$24,0) -> 0 | AD31: =MIN(AD$23,AC31) -> 0 | AE31: =IF(AND(AD$24=1,OR(AC$25="",$C31>=AC$25)),MAX(0,MIN(AC31-AD31,$D31-(G31+K31+O31+S31+W31+AA31))),0) -> 0 | AF31: =AC31-AD31-AE31 -> 0 | AG31: =IF(AJ30>0.5,AJ30*(1+AG$23)+AG$24,0) -> 0 | AH31: =MIN(AH$23,AG31) -> 0 | AI31: =IF(AND(AH$24=1,OR(AG$25="",$C31>=AG$25)),MAX(0,MIN(AG31-AH31,$D31-(G31+K31+O31+S31+W31+AA31+AE31))),0) -> 0 | AJ31: =AG31-AH31-AI31 -> 0 | AK31: =IF(AK30>0.5,AK30*(1+$E$12)+$G$12-MIN($F$12,AK30*(1+$E$12)+$G$12),0) -> 0 | AL31: =IF(AL30>0.5,AL30*(1+$E$13)+$G$13-MIN($F$13,AL30*(1+$E$13)+$G$13),0) -> 0 | AM31: =IF(AM30>0.5,AM30*(1+$E$14)+$G$14-MIN($F$14,AM30*(1+$E$14)+$G$14),0) -> 0 | AN31: =IF(AN30>0.5,AN30*(1+$E$15)+$G$15-MIN($F$15,AN30*(1+$E$15)+$G$15),0) -> 0 | AO31: =IF(AO30>0.5,AO30*(1+$E$16)+$G$16-MIN($F$16,AO30*(1+$E$16)+$G$16),0) -> 0 | AP31: =IF(AP30>0.5,AP30*(1+$E$17)+$G$17-MIN($F$17,AP30*(1+$E$17)+$G$17),0) -> 0 | AQ31: =IF(AQ30>0.5,AQ30*(1+$E$18)+$G$18-MIN($F$18,AQ30*(1+$E$18)+$G$18),0) -> 0 | AR31: =IF(AR30>0.5,AR30*(1+$E$19)+$G$19-MIN($F$19,AR30*(1+$E$19)+$G$19),0) -> 0 | AS31: =H31+L31+P31+T31+X31+AB31+AF31+AJ31 -> 0 | AT31: =SUM(AK31:AR31) -> 0 | AU31: =F31+G31+J31+K31+N31+O31+R31+S31+V31+W31+Z31+AA31+AD31+AE31+AH31+AI31 -> 0
B32: 5 | C32: =EDATE($C$7,4) -> 46419 | D32: =$C$8-(F32+J32+N32+R32+V32+Z32+AD32+AH32) -> 0 | E32: =IF(H31>0.5,H31*(1+E$23)+E$24,0) -> 0 | F32: =MIN(F$23,E32) -> 0 | G32: =IF(AND(F$24=1,OR(E$25="",$C32>=E$25)),MAX(0,MIN(E32-F32,$D32-(0))),0) -> 0 | H32: =E32-F32-G32 -> 0 | I32: =IF(L31>0.5,L31*(1+I$23)+I$24,0) -> 0 | J32: =MIN(J$23,I32) -> 0 | K32: =IF(AND(J$24=1,OR(I$25="",$C32>=I$25)),MAX(0,MIN(I32-J32,$D32-(G32))),0) -> 0 | L32: =I32-J32-K32 -> 0 | M32: =IF(P31>0.5,P31*(1+M$23)+M$24,0) -> 0 | N32: =MIN(N$23,M32) -> 0 | O32: =IF(AND(N$24=1,OR(M$25="",$C32>=M$25)),MAX(0,MIN(M32-N32,$D32-(G32+K32))),0) -> 0 | P32: =M32-N32-O32 -> 0 | Q32: =IF(T31>0.5,T31*(1+Q$23)+Q$24,0) -> 0 | R32: =MIN(R$23,Q32) -> 0 | S32: =IF(AND(R$24=1,OR(Q$25="",$C32>=Q$25)),MAX(0,MIN(Q32-R32,$D32-(G32+K32+O32))),0) -> 0 | T32: =Q32-R32-S32 -> 0 | U32: =IF(X31>0.5,X31*(1+U$23)+U$24,0) -> 0 | V32: =MIN(V$23,U32) -> 0 | W32: =IF(AND(V$24=1,OR(U$25="",$C32>=U$25)),MAX(0,MIN(U32-V32,$D32-(G32+K32+O32+S32))),0) -> 0 | X32: =U32-V32-W32 -> 0 | Y32: =IF(AB31>0.5,AB31*(1+Y$23)+Y$24,0) -> 0 | Z32: =MIN(Z$23,Y32) -> 0 | AA32: =IF(AND(Z$24=1,OR(Y$25="",$C32>=Y$25)),MAX(0,MIN(Y32-Z32,$D32-(G32+K32+O32+S32+W32))),0) -> 0 | AB32: =Y32-Z32-AA32 -> 0 | AC32: =IF(AF31>0.5,AF31*(1+AC$23)+AC$24,0) -> 0 | AD32: =MIN(AD$23,AC32) -> 0 | AE32: =IF(AND(AD$24=1,OR(AC$25="",$C32>=AC$25)),MAX(0,MIN(AC32-AD32,$D32-(G32+K32+O32+S32+W32+AA32))),0) -> 0 | AF32: =AC32-AD32-AE32 -> 0 | AG32: =IF(AJ31>0.5,AJ31*(1+AG$23)+AG$24,0) -> 0 | AH32: =MIN(AH$23,AG32) -> 0 | AI32: =IF(AND(AH$24=1,OR(AG$25="",$C32>=AG$25)),MAX(0,MIN(AG32-AH32,$D32-(G32+K32+O32+S32+W32+AA32+AE32))),0) -> 0 | AJ32: =AG32-AH32-AI32 -> 0 | AK32: =IF(AK31>0.5,AK31*(1+$E$12)+$G$12-MIN($F$12,AK31*(1+$E$12)+$G$12),0) -> 0 | AL32: =IF(AL31>0.5,AL31*(1+$E$13)+$G$13-MIN($F$13,AL31*(1+$E$13)+$G$13),0) -> 0 | AM32: =IF(AM31>0.5,AM31*(1+$E$14)+$G$14-MIN($F$14,AM31*(1+$E$14)+$G$14),0) -> 0 | AN32: =IF(AN31>0.5,AN31*(1+$E$15)+$G$15-MIN($F$15,AN31*(1+$E$15)+$G$15),0) -> 0 | AO32: =IF(AO31>0.5,AO31*(1+$E$16)+$G$16-MIN($F$16,AO31*(1+$E$16)+$G$16),0) -> 0 | AP32: =IF(AP31>0.5,AP31*(1+$E$17)+$G$17-MIN($F$17,AP31*(1+$E$17)+$G$17),0) -> 0 | AQ32: =IF(AQ31>0.5,AQ31*(1+$E$18)+$G$18-MIN($F$18,AQ31*(1+$E$18)+$G$18),0) -> 0 | AR32: =IF(AR31>0.5,AR31*(1+$E$19)+$G$19-MIN($F$19,AR31*(1+$E$19)+$G$19),0) -> 0 | AS32: =H32+L32+P32+T32+X32+AB32+AF32+AJ32 -> 0 | AT32: =SUM(AK32:AR32) -> 0 | AU32: =F32+G32+J32+K32+N32+O32+R32+S32+V32+W32+Z32+AA32+AD32+AE32+AH32+AI32 -> 0
B33: 6 | C33: =EDATE($C$7,5) -> 46447 | D33: =$C$8-(F33+J33+N33+R33+V33+Z33+AD33+AH33) -> 0 | E33: =IF(H32>0.5,H32*(1+E$23)+E$24,0) -> 0 | F33: =MIN(F$23,E33) -> 0 | G33: =IF(AND(F$24=1,OR(E$25="",$C33>=E$25)),MAX(0,MIN(E33-F33,$D33-(0))),0) -> 0 | H33: =E33-F33-G33 -> 0 | I33: =IF(L32>0.5,L32*(1+I$23)+I$24,0) -> 0 | J33: =MIN(J$23,I33) -> 0 | K33: =IF(AND(J$24=1,OR(I$25="",$C33>=I$25)),MAX(0,MIN(I33-J33,$D33-(G33))),0) -> 0 | L33: =I33-J33-K33 -> 0 | M33: =IF(P32>0.5,P32*(1+M$23)+M$24,0) -> 0 | N33: =MIN(N$23,M33) -> 0 | O33: =IF(AND(N$24=1,OR(M$25="",$C33>=M$25)),MAX(0,MIN(M33-N33,$D33-(G33+K33))),0) -> 0 | P33: =M33-N33-O33 -> 0 | Q33: =IF(T32>0.5,T32*(1+Q$23)+Q$24,0) -> 0 | R33: =MIN(R$23,Q33) -> 0 | S33: =IF(AND(R$24=1,OR(Q$25="",$C33>=Q$25)),MAX(0,MIN(Q33-R33,$D33-(G33+K33+O33))),0) -> 0 | T33: =Q33-R33-S33 -> 0 | U33: =IF(X32>0.5,X32*(1+U$23)+U$24,0) -> 0 | V33: =MIN(V$23,U33) -> 0 | W33: =IF(AND(V$24=1,OR(U$25="",$C33>=U$25)),MAX(0,MIN(U33-V33,$D33-(G33+K33+O33+S33))),0) -> 0 | X33: =U33-V33-W33 -> 0 | Y33: =IF(AB32>0.5,AB32*(1+Y$23)+Y$24,0) -> 0 | Z33: =MIN(Z$23,Y33) -> 0 | AA33: =IF(AND(Z$24=1,OR(Y$25="",$C33>=Y$25)),MAX(0,MIN(Y33-Z33,$D33-(G33+K33+O33+S33+W33))),0) -> 0 | AB33: =Y33-Z33-AA33 -> 0 | AC33: =IF(AF32>0.5,AF32*(1+AC$23)+AC$24,0) -> 0 | AD33: =MIN(AD$23,AC33) -> 0 | AE33: =IF(AND(AD$24=1,OR(AC$25="",$C33>=AC$25)),MAX(0,MIN(AC33-AD33,$D33-(G33+K33+O33+S33+W33+AA33))),0) -> 0 | AF33: =AC33-AD33-AE33 -> 0 | AG33: =IF(AJ32>0.5,AJ32*(1+AG$23)+AG$24,0) -> 0 | AH33: =MIN(AH$23,AG33) -> 0 | AI33: =IF(AND(AH$24=1,OR(AG$25="",$C33>=AG$25)),MAX(0,MIN(AG33-AH33,$D33-(G33+K33+O33+S33+W33+AA33+AE33))),0) -> 0 | AJ33: =AG33-AH33-AI33 -> 0 | AK33: =IF(AK32>0.5,AK32*(1+$E$12)+$G$12-MIN($F$12,AK32*(1+$E$12)+$G$12),0) -> 0 | AL33: =IF(AL32>0.5,AL32*(1+$E$13)+$G$13-MIN($F$13,AL32*(1+$E$13)+$G$13),0) -> 0 | AM33: =IF(AM32>0.5,AM32*(1+$E$14)+$G$14-MIN($F$14,AM32*(1+$E$14)+$G$14),0) -> 0 | AN33: =IF(AN32>0.5,AN32*(1+$E$15)+$G$15-MIN($F$15,AN32*(1+$E$15)+$G$15),0) -> 0 | AO33: =IF(AO32>0.5,AO32*(1+$E$16)+$G$16-MIN($F$16,AO32*(1+$E$16)+$G$16),0) -> 0 | AP33: =IF(AP32>0.5,AP32*(1+$E$17)+$G$17-MIN($F$17,AP32*(1+$E$17)+$G$17),0) -> 0 | AQ33: =IF(AQ32>0.5,AQ32*(1+$E$18)+$G$18-MIN($F$18,AQ32*(1+$E$18)+$G$18),0) -> 0 | AR33: =IF(AR32>0.5,AR32*(1+$E$19)+$G$19-MIN($F$19,AR32*(1+$E$19)+$G$19),0) -> 0 | AS33: =H33+L33+P33+T33+X33+AB33+AF33+AJ33 -> 0 | AT33: =SUM(AK33:AR33) -> 0 | AU33: =F33+G33+J33+K33+N33+O33+R33+S33+V33+W33+Z33+AA33+AD33+AE33+AH33+AI33 -> 0
B34: 7 | C34: =EDATE($C$7,6) -> 46478 | D34: =$C$8-(F34+J34+N34+R34+V34+Z34+AD34+AH34) -> 0 | E34: =IF(H33>0.5,H33*(1+E$23)+E$24,0) -> 0 | F34: =MIN(F$23,E34) -> 0 | G34: =IF(AND(F$24=1,OR(E$25="",$C34>=E$25)),MAX(0,MIN(E34-F34,$D34-(0))),0) -> 0 | H34: =E34-F34-G34 -> 0 | I34: =IF(L33>0.5,L33*(1+I$23)+I$24,0) -> 0 | J34: =MIN(J$23,I34) -> 0 | K34: =IF(AND(J$24=1,OR(I$25="",$C34>=I$25)),MAX(0,MIN(I34-J34,$D34-(G34))),0) -> 0 | L34: =I34-J34-K34 -> 0 | M34: =IF(P33>0.5,P33*(1+M$23)+M$24,0) -> 0 | N34: =MIN(N$23,M34) -> 0 | O34: =IF(AND(N$24=1,OR(M$25="",$C34>=M$25)),MAX(0,MIN(M34-N34,$D34-(G34+K34))),0) -> 0 | P34: =M34-N34-O34 -> 0 | Q34: =IF(T33>0.5,T33*(1+Q$23)+Q$24,0) -> 0 | R34: =MIN(R$23,Q34) -> 0 | S34: =IF(AND(R$24=1,OR(Q$25="",$C34>=Q$25)),MAX(0,MIN(Q34-R34,$D34-(G34+K34+O34))),0) -> 0 | T34: =Q34-R34-S34 -> 0 | U34: =IF(X33>0.5,X33*(1+U$23)+U$24,0) -> 0 | V34: =MIN(V$23,U34) -> 0 | W34: =IF(AND(V$24=1,OR(U$25="",$C34>=U$25)),MAX(0,MIN(U34-V34,$D34-(G34+K34+O34+S34))),0) -> 0 | X34: =U34-V34-W34 -> 0 | Y34: =IF(AB33>0.5,AB33*(1+Y$23)+Y$24,0) -> 0 | Z34: =MIN(Z$23,Y34) -> 0 | AA34: =IF(AND(Z$24=1,OR(Y$25="",$C34>=Y$25)),MAX(0,MIN(Y34-Z34,$D34-(G34+K34+O34+S34+W34))),0) -> 0 | AB34: =Y34-Z34-AA34 -> 0 | AC34: =IF(AF33>0.5,AF33*(1+AC$23)+AC$24,0) -> 0 | AD34: =MIN(AD$23,AC34) -> 0 | AE34: =IF(AND(AD$24=1,OR(AC$25="",$C34>=AC$25)),MAX(0,MIN(AC34-AD34,$D34-(G34+K34+O34+S34+W34+AA34))),0) -> 0 | AF34: =AC34-AD34-AE34 -> 0 | AG34: =IF(AJ33>0.5,AJ33*(1+AG$23)+AG$24,0) -> 0 | AH34: =MIN(AH$23,AG34) -> 0 | AI34: =IF(AND(AH$24=1,OR(AG$25="",$C34>=AG$25)),MAX(0,MIN(AG34-AH34,$D34-(G34+K34+O34+S34+W34+AA34+AE34))),0) -> 0 | AJ34: =AG34-AH34-AI34 -> 0 | AK34: =IF(AK33>0.5,AK33*(1+$E$12)+$G$12-MIN($F$12,AK33*(1+$E$12)+$G$12),0) -> 0 | AL34: =IF(AL33>0.5,AL33*(1+$E$13)+$G$13-MIN($F$13,AL33*(1+$E$13)+$G$13),0) -> 0 | AM34: =IF(AM33>0.5,AM33*(1+$E$14)+$G$14-MIN($F$14,AM33*(1+$E$14)+$G$14),0) -> 0 | AN34: =IF(AN33>0.5,AN33*(1+$E$15)+$G$15-MIN($F$15,AN33*(1+$E$15)+$G$15),0) -> 0 | AO34: =IF(AO33>0.5,AO33*(1+$E$16)+$G$16-MIN($F$16,AO33*(1+$E$16)+$G$16),0) -> 0 | AP34: =IF(AP33>0.5,AP33*(1+$E$17)+$G$17-MIN($F$17,AP33*(1+$E$17)+$G$17),0) -> 0 | AQ34: =IF(AQ33>0.5,AQ33*(1+$E$18)+$G$18-MIN($F$18,AQ33*(1+$E$18)+$G$18),0) -> 0 | AR34: =IF(AR33>0.5,AR33*(1+$E$19)+$G$19-MIN($F$19,AR33*(1+$E$19)+$G$19),0) -> 0 | AS34: =H34+L34+P34+T34+X34+AB34+AF34+AJ34 -> 0 | AT34: =SUM(AK34:AR34) -> 0 | AU34: =F34+G34+J34+K34+N34+O34+R34+S34+V34+W34+Z34+AA34+AD34+AE34+AH34+AI34 -> 0
B35: 8 | C35: =EDATE($C$7,7) -> 46508 | D35: =$C$8-(F35+J35+N35+R35+V35+Z35+AD35+AH35) -> 0 | E35: =IF(H34>0.5,H34*(1+E$23)+E$24,0) -> 0 | F35: =MIN(F$23,E35) -> 0 | G35: =IF(AND(F$24=1,OR(E$25="",$C35>=E$25)),MAX(0,MIN(E35-F35,$D35-(0))),0) -> 0 | H35: =E35-F35-G35 -> 0 | I35: =IF(L34>0.5,L34*(1+I$23)+I$24,0) -> 0 | J35: =MIN(J$23,I35) -> 0 | K35: =IF(AND(J$24=1,OR(I$25="",$C35>=I$25)),MAX(0,MIN(I35-J35,$D35-(G35))),0) -> 0 | L35: =I35-J35-K35 -> 0 | M35: =IF(P34>0.5,P34*(1+M$23)+M$24,0) -> 0 | N35: =MIN(N$23,M35) -> 0 | O35: =IF(AND(N$24=1,OR(M$25="",$C35>=M$25)),MAX(0,MIN(M35-N35,$D35-(G35+K35))),0) -> 0 | P35: =M35-N35-O35 -> 0 | Q35: =IF(T34>0.5,T34*(1+Q$23)+Q$24,0) -> 0 | R35: =MIN(R$23,Q35) -> 0 | S35: =IF(AND(R$24=1,OR(Q$25="",$C35>=Q$25)),MAX(0,MIN(Q35-R35,$D35-(G35+K35+O35))),0) -> 0 | T35: =Q35-R35-S35 -> 0 | U35: =IF(X34>0.5,X34*(1+U$23)+U$24,0) -> 0 | V35: =MIN(V$23,U35) -> 0 | W35: =IF(AND(V$24=1,OR(U$25="",$C35>=U$25)),MAX(0,MIN(U35-V35,$D35-(G35+K35+O35+S35))),0) -> 0 | X35: =U35-V35-W35 -> 0 | Y35: =IF(AB34>0.5,AB34*(1+Y$23)+Y$24,0) -> 0 | Z35: =MIN(Z$23,Y35) -> 0 | AA35: =IF(AND(Z$24=1,OR(Y$25="",$C35>=Y$25)),MAX(0,MIN(Y35-Z35,$D35-(G35+K35+O35+S35+W35))),0) -> 0 | AB35: =Y35-Z35-AA35 -> 0 | AC35: =IF(AF34>0.5,AF34*(1+AC$23)+AC$24,0) -> 0 | AD35: =MIN(AD$23,AC35) -> 0 | AE35: =IF(AND(AD$24=1,OR(AC$25="",$C35>=AC$25)),MAX(0,MIN(AC35-AD35,$D35-(G35+K35+O35+S35+W35+AA35))),0) -> 0 | AF35: =AC35-AD35-AE35 -> 0 | AG35: =IF(AJ34>0.5,AJ34*(1+AG$23)+AG$24,0) -> 0 | AH35: =MIN(AH$23,AG35) -> 0 | AI35: =IF(AND(AH$24=1,OR(AG$25="",$C35>=AG$25)),MAX(0,MIN(AG35-AH35,$D35-(G35+K35+O35+S35+W35+AA35+AE35))),0) -> 0 | AJ35: =AG35-AH35-AI35 -> 0 | AK35: =IF(AK34>0.5,AK34*(1+$E$12)+$G$12-MIN($F$12,AK34*(1+$E$12)+$G$12),0) -> 0 | AL35: =IF(AL34>0.5,AL34*(1+$E$13)+$G$13-MIN($F$13,AL34*(1+$E$13)+$G$13),0) -> 0 | AM35: =IF(AM34>0.5,AM34*(1+$E$14)+$G$14-MIN($F$14,AM34*(1+$E$14)+$G$14),0) -> 0 | AN35: =IF(AN34>0.5,AN34*(1+$E$15)+$G$15-MIN($F$15,AN34*(1+$E$15)+$G$15),0) -> 0 | AO35: =IF(AO34>0.5,AO34*(1+$E$16)+$G$16-MIN($F$16,AO34*(1+$E$16)+$G$16),0) -> 0 | AP35: =IF(AP34>0.5,AP34*(1+$E$17)+$G$17-MIN($F$17,AP34*(1+$E$17)+$G$17),0) -> 0 | AQ35: =IF(AQ34>0.5,AQ34*(1+$E$18)+$G$18-MIN($F$18,AQ34*(1+$E$18)+$G$18),0) -> 0 | AR35: =IF(AR34>0.5,AR34*(1+$E$19)+$G$19-MIN($F$19,AR34*(1+$E$19)+$G$19),0) -> 0 | AS35: =H35+L35+P35+T35+X35+AB35+AF35+AJ35 -> 0 | AT35: =SUM(AK35:AR35) -> 0 | AU35: =F35+G35+J35+K35+N35+O35+R35+S35+V35+W35+Z35+AA35+AD35+AE35+AH35+AI35 -> 0
B36: 9 | C36: =EDATE($C$7,8) -> 46539 | D36: =$C$8-(F36+J36+N36+R36+V36+Z36+AD36+AH36) -> 0 | E36: =IF(H35>0.5,H35*(1+E$23)+E$24,0) -> 0 | F36: =MIN(F$23,E36) -> 0 | G36: =IF(AND(F$24=1,OR(E$25="",$C36>=E$25)),MAX(0,MIN(E36-F36,$D36-(0))),0) -> 0 | H36: =E36-F36-G36 -> 0 | I36: =IF(L35>0.5,L35*(1+I$23)+I$24,0) -> 0 | J36: =MIN(J$23,I36) -> 0 | K36: =IF(AND(J$24=1,OR(I$25="",$C36>=I$25)),MAX(0,MIN(I36-J36,$D36-(G36))),0) -> 0 | L36: =I36-J36-K36 -> 0 | M36: =IF(P35>0.5,P35*(1+M$23)+M$24,0) -> 0 | N36: =MIN(N$23,M36) -> 0 | O36: =IF(AND(N$24=1,OR(M$25="",$C36>=M$25)),MAX(0,MIN(M36-N36,$D36-(G36+K36))),0) -> 0 | P36: =M36-N36-O36 -> 0 | Q36: =IF(T35>0.5,T35*(1+Q$23)+Q$24,0) -> 0 | R36: =MIN(R$23,Q36) -> 0 | S36: =IF(AND(R$24=1,OR(Q$25="",$C36>=Q$25)),MAX(0,MIN(Q36-R36,$D36-(G36+K36+O36))),0) -> 0 | T36: =Q36-R36-S36 -> 0 | U36: =IF(X35>0.5,X35*(1+U$23)+U$24,0) -> 0 | V36: =MIN(V$23,U36) -> 0 | W36: =IF(AND(V$24=1,OR(U$25="",$C36>=U$25)),MAX(0,MIN(U36-V36,$D36-(G36+K36+O36+S36))),0) -> 0 | X36: =U36-V36-W36 -> 0 | Y36: =IF(AB35>0.5,AB35*(1+Y$23)+Y$24,0) -> 0 | Z36: =MIN(Z$23,Y36) -> 0 | AA36: =IF(AND(Z$24=1,OR(Y$25="",$C36>=Y$25)),MAX(0,MIN(Y36-Z36,$D36-(G36+K36+O36+S36+W36))),0) -> 0 | AB36: =Y36-Z36-AA36 -> 0 | AC36: =IF(AF35>0.5,AF35*(1+AC$23)+AC$24,0) -> 0 | AD36: =MIN(AD$23,AC36) -> 0 | AE36: =IF(AND(AD$24=1,OR(AC$25="",$C36>=AC$25)),MAX(0,MIN(AC36-AD36,$D36-(G36+K36+O36+S36+W36+AA36))),0) -> 0 | AF36: =AC36-AD36-AE36 -> 0 | AG36: =IF(AJ35>0.5,AJ35*(1+AG$23)+AG$24,0) -> 0 | AH36: =MIN(AH$23,AG36) -> 0 | AI36: =IF(AND(AH$24=1,OR(AG$25="",$C36>=AG$25)),MAX(0,MIN(AG36-AH36,$D36-(G36+K36+O36+S36+W36+AA36+AE36))),0) -> 0 | AJ36: =AG36-AH36-AI36 -> 0 | AK36: =IF(AK35>0.5,AK35*(1+$E$12)+$G$12-MIN($F$12,AK35*(1+$E$12)+$G$12),0) -> 0 | AL36: =IF(AL35>0.5,AL35*(1+$E$13)+$G$13-MIN($F$13,AL35*(1+$E$13)+$G$13),0) -> 0 | AM36: =IF(AM35>0.5,AM35*(1+$E$14)+$G$14-MIN($F$14,AM35*(1+$E$14)+$G$14),0) -> 0 | AN36: =IF(AN35>0.5,AN35*(1+$E$15)+$G$15-MIN($F$15,AN35*(1+$E$15)+$G$15),0) -> 0 | AO36: =IF(AO35>0.5,AO35*(1+$E$16)+$G$16-MIN($F$16,AO35*(1+$E$16)+$G$16),0) -> 0 | AP36: =IF(AP35>0.5,AP35*(1+$E$17)+$G$17-MIN($F$17,AP35*(1+$E$17)+$G$17),0) -> 0 | AQ36: =IF(AQ35>0.5,AQ35*(1+$E$18)+$G$18-MIN($F$18,AQ35*(1+$E$18)+$G$18),0) -> 0 | AR36: =IF(AR35>0.5,AR35*(1+$E$19)+$G$19-MIN($F$19,AR35*(1+$E$19)+$G$19),0) -> 0 | AS36: =H36+L36+P36+T36+X36+AB36+AF36+AJ36 -> 0 | AT36: =SUM(AK36:AR36) -> 0 | AU36: =F36+G36+J36+K36+N36+O36+R36+S36+V36+W36+Z36+AA36+AD36+AE36+AH36+AI36 -> 0
