Workbook

Sheet Inicio
C2: Asesoría Financiera Personal
C3: =IF(Supuestos!$C$6="","Tu marca aquí (Supuestos)",Supuestos!$C$6) -> Tu marca aquí (Supuestos)
C7: Cliente | D7: =IF(Supuestos!$C$7="","",Supuestos!$C$7)
C8: Fecha de corte | D8: =Supuestos!$C$12 -> 46290
B10: Orden para llenar
B11: Paso | C11: Hoja | D11: Qué hacer
B12: 1 | C12: Supuestos | D12: Datos del cliente, tasa de cambio, prueba de realidad y cuentas por cobrar.
B13: 2 | C13: Ingresos | D13: Cada fuente en su moneda (pesos o dólares); 1 o 0 en los meses en que llega. Meses de pago de seguridad social.
B14: 3 | C14: Presupuesto | D14: Valor por pago y frecuencia de cada gasto. Las filas grises son automáticas.
B15: 4 | C15: Deudas | D15: Saldo, tasa efectiva anual, cuota mínima y si acepta abonos extra. Elegir el método de pago.
B16: 5 | C16: Metas | D16: Metas con valor y fecha, o que se repiten. Calculadora de viaje en dólares.
B17: 6 | C17: Seguros | D17: Marcar qué seguros tiene y escribir primas de seguros nuevos.
B18: 7 | C18: Patrimonio | D18: Cuentas, inmuebles, vehículos y otros activos.
B19: 8 | C19: Inversión | D19: Inversiones actuales y las preguntas de perfil de riesgo.
B20: 9 | C20: Pensión | D20: Régimen, semanas, fecha y base de cotización.
B21: 10 | C21: Bolsillos | D21: Revisar el reparto del saldo y escribir saldos iniciales de otros bolsillos.
B22: 11 | C22: Resumen | D22: Revisar indicadores, estados y la lista de pendientes.
B23: 12 | C23: Control mensual y Plan de acción | D23: Seguimiento: gasto real cada mes y tareas con fecha.
B25: Leyenda
C26: Dato editable | D26: Celda para llenar o ajustar.
C27: Por confirmar | D27: Dato pendiente de confirmar.
C28: Cálculo automático | D28: Fórmula: no se edita.
C29: Fila automática | D29: Se llena desde otra hoja: no se edita.
C30: Color de las pestañas | D30: Dorada: tiene datos para llenar. Verde azulado: solo cálculos. Petróleo: portada y resumen.
B32: Ejemplo de una fila del Presupuesto
C33: Categoría | D33: Concepto | E33: Valor por pago | F33: Frecuencia | G33: Tipo / ¿Esencial?
C34: Alimentación | D34: Mercado | E34: 130000 | F34: Semanal | G34: Directo / Sí
C35: Resultado: 130.000 x 52 semanas = 6.760.000 al año, 563.333 al mes.
B37: Notas
C38: Todas las cifras están en pesos de hoy (sin inflación).
C39: Los rangos de inversión y las proyecciones son orientativos y no garantizan rendimientos. No se recomiendan productos específicos.
C40: Salario mínimo, tasa de cambio y reglas de pensión deben verificarse al inicio de cada asesoría.
C41: Impuestos, pensión y temas legales se validan con contador, administradora de pensiones y abogado.
B43: Paleta de la marca: Petróleo y Oro
C44: Petróleo | D44: #0E3B43
C45: Verde azulado | D45: #1D6A72
C46: Oro | D46: #C8A04A
C47: Bruma | D47: #E6EFEF
C48: Crema | D48: #FFF8E6

Sheet Resumen
B1: Resumen financiero
B2: Indicadores principales. Pesos de hoy. Estados: Bien, Atención, Alerta (referencias orientativas).
B4: Cliente | C4: =IF(Supuestos!$C$7="","",Supuestos!$C$7)
B5: Edad | C5: =Supuestos!$C$13
B6: Tipo de cliente | C6: =IF(Supuestos!$C$10="","",Supuestos!$C$10)
B7: Fecha de corte | C7: =Supuestos!$C$12 -> 46290
B8: Asesor | C8: =IF(Supuestos!$C$6="","",Supuestos!$C$6)
B10: Indicador | C10: Valor | D10: Estado | E10: Comentario
B11: Ingreso anual | C11: =Ingresos!$T$14 -> 0 | D11: ="" | E11: Suma de ingresos en sus meses reales.
B12: Gasto anual (sin ahorro) | C12: =Presupuesto!$H$89 -> 0 | D12: ="" | E12: Incluye bolsillos y cuotas de deuda.
B13: Ahorro programado anual | C13: =Presupuesto!$H$94 -> 0 | D13: ="" | E13: Cooperativas, fondos, pensión voluntaria.
B14: Sobrante anual | C14: ='Flujo anual'!$Q$22 -> 0 | D14: =IF(C14<0,"Alerta","Bien") -> Bien | E14: Después de gastos, bolsillos y ahorro programado.
B15: Tasa de ahorro total | C15: =IF(C11=0,"",(C13+C14)/C11) | D15: =IF(C15="","",IF(C15>=0.2,"Bien",IF(C15>=0.1,"Atención","Alerta"))) | E15: Referencia: sobre 20% es buena.
B16: Carga de deuda | C16: =Deudas!$C$24 | D16: =IF(C16="","",IF(C16<0.3,"Bien",IF(C16<0.4,"Atención","Alerta"))) | E16: Cuotas / ingreso mensual. Referencia: bajo 30%.
B17: Deuda total | C17: =Deudas!$D$21 -> 0 | D17: =""
B18: ¿Hay deuda cara? | C18: =Deudas!$C$23 -> No | D18: =IF(C18="Sí","Alerta","Bien") -> Bien | E18: Con deuda cara no se invierte: el sobrante va a deudas.
B19: Salida de la deuda cara | C19: =Deudas!$C$25 | D19: ="" | E19: Según la simulación de la hoja Deudas.
B20: Liquidez (meses de gasto esencial) | C20: =IF(Presupuesto!$I$95=0,"",Patrimonio!$C$33/Presupuesto!$I$95) | D20: =IF(C20="","",IF(C20>=3,"Bien",IF(C20>=1,"Atención","Alerta")))
B21: Meta vigente del fondo de emergencia | C21: ='Fondo emergencia'!$C$21 -> 0 | D21: =""
B22: Avance del fondo frente a la meta completa | C22: ='Fondo emergencia'!$C$25 -> 1 | D22: =IF(C22>=0.999,"Bien",IF(C22>=0.5,"Atención","Alerta")) -> Bien
B23: Faltante de los meses sin ingreso | C23: ='Flujo anual'!$T$20 -> 0 | D23: ="" | E23: Se cubre con su propio bolsillo.
B24: Aporte mensual a ese bolsillo | C24: ='Flujo anual'!$T$23 -> 0 | D24: ="" | E24: En los meses con sobrante.
B25: Inversión anual | C25: ='Flujo anual'!$Q$33 -> 0 | D25: ="" | E25: Incluye abonos de cuentas por cobrar destinados a inversión.
B26: Aporte único a inversión | C26: =Bolsillos!$C$27 -> 0 | D26: ="" | E26: Del excedente del saldo actual.
B27: Perfil de inversión | C27: =Inversión!$E$32 -> Falta responder | D27: ="" | E27: El menor entre disposición y capacidad.
B28: % en crecimiento | C28: =Inversión!$C$45 -> 0 | D28: ="" | E28: Rango orientativo según edad y perfil.
B29: Semanas estimadas al cumplir la edad de pensión | C29: =Pensión!$C$20 | D29: ="" | E29: =IF(Pensión!$C$22="","","Requeridas: "&ROUND(Pensión!$C$22,0))
B30: ¿Cumple las semanas? | C30: =Pensión!$C$24 | D30: =IF(C30="Sí","Bien",IF(C30="No","Alerta",""))
B31: Mesada neta estimada (escenario medio) | C31: =IF(OR(Pensión!$C$6="",Pensión!$C$13=""),"",Pensión!$D$63) | D31: ="" | E31: Solo Colpensiones. Confirmar con la administradora.
B32: ¿Brecha pensional? | C32: =Pensión!$C$78 | D32: =IF(C32="Sí","Alerta",IF(C32="No","Bien","")) | E32: Si deja de trabajar, escenario medio.
B33: Patrimonio neto | C33: =Patrimonio!$F$30 -> 0 | D33: =""
B34: Concentración en inmuebles y vehículos | C34: =Patrimonio!$C$39 -> 0 | D34: =IF(C34<=0.8,"Bien","Atención") -> Bien | E34: Referencia: más de 80% es poco líquido.
B35: Prueba de realidad | C35: =Supuestos!$C$41 -> Pendiente | D35: =IF(C35="Confirmada","Bien",IF(C35="Pendiente","Atención","Alerta")) -> Atención | E35: Mientras esté pendiente se invierte un % menor.
B37: Pendientes y alertas
B38: =IF(Supuestos!$C$8="","Falta la fecha de nacimiento (Supuestos).","") -> Falta la fecha de nacimiento (Supuestos).
B39: =IF(Supuestos!$C$17="","Falta la tasa de cambio (Supuestos).","") -> Falta la tasa de cambio (Supuestos).
B40: =IF(Supuestos!$C$41="Pendiente","Prueba de realidad pendiente: se invierte un % menor del sobrante.",IF(Supuestos!$C$41="Revisar gastos","La prueba de realidad muestra gastos no registrados: revisar el presupuesto.","")) -> Prueba de realidad pendiente: se invierte un % menor del sobrante.
B41: =IF(Presupuesto!$I$97>0,"Hay filas del presupuesto con valor pero sin frecuencia o tipo.","")
B42: ='Flujo anual'!$B$36
B43: =IF(Bolsillos!$C$25<-0.5,"Los saldos iniciales de los bolsillos superan lo disponible.","")
...

Sheet Supuestos
B1: Supuestos y datos base
B2: Celdas crema: datos que se llenan o ajustan. Celdas ámbar: por confirmar. Todo lo demás se calcula solo.
B5: Datos del cliente | D5: Nota
B6: Marca o nombre del asesor | D6: Aparece en el Inicio y el Resumen.
B7: Nombre del cliente
B8: Fecha de nacimiento | D8: Formato dd/mm/aaaa.
B9: Sexo | D9: Define edad y semanas de pensión.
B10: Tipo de cliente | D10: Define los meses de fondo de emergencia sugeridos.
B11: Personas a cargo | C11: 0 | D11: Hijos u otras personas que dependen económicamente.
B12: Fecha de corte | C12: =TODAY() -> 46290 | D12: Por defecto, hoy. Se puede escribir una fecha fija.
B13: Edad | C13: =IF(C8="","",DATEDIF(C8,C12,"y"))
B14: Año del flujo anual | C14: =YEAR(C12)+1 -> 2027 | D14: Año que se proyecta mes a mes en la hoja Flujo anual.
B16: Parámetros
B17: Tasa de cambio COP por USD | D17: Buscar la tasa oficial vigente.
B18: Salario mínimo del año | C18: 1750905 | D18: Colombia 2026. Verificar cada año.
B19: Meses de fondo de emergencia sugeridos | C19: =IFERROR(VLOOKUP(C10,Listas!$H$2:$I$7,2,FALSE()),3) -> 3 | D19: Según el tipo de cliente.
B20: Meses de fondo a usar (opcional) | D20: Déjalo vacío para usar el sugerido.
B21: Meses de fondo efectivos | C21: =IF(C20="",C19,C20) -> 3
B22: Umbral de deuda cara (tasa efectiva anual) | C22: 0.2 | D22: Ajustar según las tasas vigentes.
B23: % del sobrante a inversión (prueba de realidad confirmada) | C23: 0.7 | D23: El resto queda como margen.
B24: % del sobrante a inversión (prueba pendiente) | C24: 0.5 | D24: Más prudente mientras no se confirme el sobrante.
B25: % del sobrante a deudas cuando hay deuda cara | C25: 0.9 | D25: Con deuda cara no se invierte.
B26: % del excedente actual a inversión | C26: 0.5 | D26: Del saldo que sobra después de llenar los bolsillos.
B27: Rendimiento real supuesto: crecimiento | C27: 0.05 | D27: Ilustrativo, por encima de la inflación. No garantizado.
B28: Rendimiento real supuesto: estabilidad | C28: 0.015 | D28: Ilustrativo, por encima de la inflación. No garantizado.
B29: Edad de retiro esperada | C29: =IF(C9="Hombre",62,57) -> 57 | D29: Por defecto, la edad de pensión. Se puede cambiar.
B30: Reducción anual del % en crecimiento cerca del retiro | C30: 0.02 | D30: Se aplica en los 10 años anteriores al retiro.
B31: Piso del % en crecimiento | C31: 0.1
B32: Colchón mínimo en la cuenta operativa | C32: 0 | D32: Dinero que no se reparte en bolsillos.
B34: Prueba de realidad
B35: Ahorro total hace N meses | D35: Suma de cuentas, bolsillos e inversiones en esa fecha.
B36: N (meses)
B37: Ahorro total hoy | D37: Sin contar ingresos extraordinarios (herencias, ventas).
B38: Ahorro real mensual | C38: =IF(OR(C35="",C36="",C37=""),"",(C37-C35)/C36)
B39: Ahorro esperado mensual (sobrante + ahorro programado) | C39: =('Flujo anual'!$Q$22+Presupuesto!$H$94)/12 -> 0
B40: Diferencia | C40: =IF(C38="","",IF(C39=0,"",(C38-C39)/ABS(C39)))
B41: Estado de la prueba | C41: =IF(C38="","Pendiente",IF(C40="","Pendiente",IF(C40>=-0.15,"Confirmada","Revisar gastos"))) -> Pendiente | D41: Confirmada si el ahorro real es al menos 85% del esperado.
B42: % del sobrante a inversión aplicado | C42: =IF(C41="Confirmada",C23,C24) -> 0.5
B44: Cuentas por cobrar (dinero que le deben al cliente)
B45: Deudor | C45: Saldo | D45: Cuota mensual | E45: Fecha del primer pago | F45: N.º de cuotas | G45: Último pago | H45: % a inversión | I45: Saldo pendiente hoy | J45: Aux. inicio | K45: Aux. fin
...

Sheet Ingresos
B1: Ingresos
B2: Un renglón por fuente, en su moneda. En los meses escribe 1 si el ingreso llega ese mes y 0 si no. Valores netos (lo que llega a la cuenta).
B5: Fuente | C5: Tipo | D5: Moneda | E5: Valor mensual en su moneda | F5: Valor mensual en pesos | G5: Ene | H5: Feb | I5: Mar | J5: Abr | K5: May | L5: Jun | M5: Jul | N5: Ago | O5: Sep | P5: Oct | Q5: Nov | R5: Dic | S5: Meses | T5: Total anual | U5: Promedio mensual | V5: Nota
D6: COP | F6: =IF(N(E6)=0,0,IF(D6="USD",E6*N(Supuestos!$C$17),E6)) -> 0 | G6: 1 | H6: 1 | I6: 1 | J6: 1 | K6: 1 | L6: 1 | M6: 1 | N6: 1 | O6: 1 | P6: 1 | Q6: 1 | R6: 1 | S6: =SUM(G6:R6) -> 12 | T6: =F6*S6 -> 0 | U6: =T6/12 -> 0
D7: COP | F7: =IF(N(E7)=0,0,IF(D7="USD",E7*N(Supuestos!$C$17),E7)) -> 0 | G7: 1 | H7: 1 | I7: 1 | J7: 1 | K7: 1 | L7: 1 | M7: 1 | N7: 1 | O7: 1 | P7: 1 | Q7: 1 | R7: 1 | S7: =SUM(G7:R7) -> 12 | T7: =F7*S7 -> 0 | U7: =T7/12 -> 0
D8: COP | F8: =IF(N(E8)=0,0,IF(D8="USD",E8*N(Supuestos!$C$17),E8)) -> 0 | G8: 1 | H8: 1 | I8: 1 | J8: 1 | K8: 1 | L8: 1 | M8: 1 | N8: 1 | O8: 1 | P8: 1 | Q8: 1 | R8: 1 | S8: =SUM(G8:R8) -> 12 | T8: =F8*S8 -> 0 | U8: =T8/12 -> 0
D9: COP | F9: =IF(N(E9)=0,0,IF(D9="USD",E9*N(Supuestos!$C$17),E9)) -> 0 | G9: 1 | H9: 1 | I9: 1 | J9: 1 | K9: 1 | L9: 1 | M9: 1 | N9: 1 | O9: 1 | P9: 1 | Q9: 1 | R9: 1 | S9: =SUM(G9:R9) -> 12 | T9: =F9*S9 -> 0 | U9: =T9/12 -> 0
D10: COP | F10: =IF(N(E10)=0,0,IF(D10="USD",E10*N(Supuestos!$C$17),E10)) -> 0 | G10: 1 | H10: 1 | I10: 1 | J10: 1 | K10: 1 | L10: 1 | M10: 1 | N10: 1 | O10: 1 | P10: 1 | Q10: 1 | R10: 1 | S10: =SUM(G10:R10) -> 12 | T10: =F10*S10 -> 0 | U10: =T10/12 -> 0
D11: COP | F11: =IF(N(E11)=0,0,IF(D11="USD",E11*N(Supuestos!$C$17),E11)) -> 0 | G11: 1 | H11: 1 | I11: 1 | J11: 1 | K11: 1 | L11: 1 | M11: 1 | N11: 1 | O11: 1 | P11: 1 | Q11: 1 | R11: 1 | S11: =SUM(G11:R11) -> 12 | T11: =F11*S11 -> 0 | U11: =T11/12 -> 0
D12: COP | F12: =IF(N(E12)=0,0,IF(D12="USD",E12*N(Supuestos!$C$17),E12)) -> 0 | G12: 1 | H12: 1 | I12: 1 | J12: 1 | K12: 1 | L12: 1 | M12: 1 | N12: 1 | O12: 1 | P12: 1 | Q12: 1 | R12: 1 | S12: =SUM(G12:R12) -> 12 | T12: =F12*S12 -> 0 | U12: =T12/12 -> 0
D13: COP | F13: =IF(N(E13)=0,0,IF(D13="USD",E13*N(Supuestos!$C$17),E13)) -> 0 | G13: 1 | H13: 1 | I13: 1 | J13: 1 | K13: 1 | L13: 1 | M13: 1 | N13: 1 | O13: 1 | P13: 1 | Q13: 1 | R13: 1 | S13: =SUM(G13:R13) -> 12 | T13: =F13*S13 -> 0 | U13: =T13/12 -> 0
B14: Total por mes | G14: =SUMPRODUCT($F$6:$F$13,G6:G13) -> 0 | H14: =SUMPRODUCT($F$6:$F$13,H6:H13) -> 0 | I14: =SUMPRODUCT($F$6:$F$13,I6:I13) -> 0 | J14: =SUMPRODUCT($F$6:$F$13,J6:J13) -> 0 | K14: =SUMPRODUCT($F$6:$F$13,K6:K13) -> 0 | L14: =SUMPRODUCT($F$6:$F$13,L6:L13) -> 0 | M14: =SUMPRODUCT($F$6:$F$13,M6:M13) -> 0 | N14: =SUMPRODUCT($F$6:$F$13,N6:N13) -> 0 | ... R14: =SUMPRODUCT($F$6:$F$13,R6:R13) -> 0 | T14: =SUM(T6:T13) -> 0 | U14: =T14/12 -> 0
G15: Totales por mes en miles de pesos. Ingresos en dólares: se convierten con la tasa de cambio de Supuestos.
B16: Seguridad social
B17: ¿Se paga seguridad social este mes? (1 = sí) | G17: 1 | H17: 1 | I17: 1 | J17: 1 | K17: 1 | L17: 1 | M17: 1 | N17: 1 | O17: 1 | P17: 1 | Q17: 1 | R17: 1 | S17: =SUM(G17:R17) -> 12 | V17: Si se cotiza mes vencido, el mes siguiente al primer mes sin contrato suele no tener pago.
B19: Totales por tipo de ingreso
B20: Laboral | T20: =SUMIFS($T$6:$T$13,$C$6:$C$13,B20) -> 0 | U20: =T20/12 -> 0
B21: Renta | T21: =SUMIFS($T$6:$T$13,$C$6:$C$13,B21) -> 0 | U21: =T21/12 -> 0
B22: Pensión | T22: =SUMIFS($T$6:$T$13,$C$6:$C$13,B22) -> 0 | U22: =T22/12 -> 0
B23: Otro | T23: =SUMIFS($T$6:$T$13,$C$6:$C$13,B23) -> 0 | U23: =T23/12 -> 0
B24: Total | T24: =SUM(T20:T23) -> 0 | U24: =T24/12 -> 0
B25: De ese total, ingreso anual en dólares (USD) | T25: =SUMPRODUCT((D6:D13="USD")*E6:E13*S6:S13) -> 0
B27: Calculadora de ingreso base (para ingresos variables)
B28: Ingreso de cada uno de los últimos 12 meses | G28: Mes 1 | H28: Mes 2 | I28: Mes 3 | J28: Mes 4 | K28: Mes 5 | L28: Mes 6 | M28: Mes 7 | N28: Mes 8 | O28: Mes 9 | P28: Mes 10 | Q28: Mes 11 | R28: Mes 12
B29: Valores (en su moneda)
B30: Promedio de 12 meses | E30: =IF(COUNT(G29:R29)=0,"",AVERAGE(G29:R29))
B31: Promedio de los 3 meses más bajos | E31: =IF(COUNT(G29:R29)<3,"",(SMALL(G29:R29,1)+SMALL(G29:R29,2)+SMALL(G29:R29,3))/3)
B32: Ingreso base sugerido | E32: =IF(OR(E30="",E31=""),"",MIN(E30,E31)) | G32: Escribe este valor como "Valor mensual en su moneda" de la fuente variable. Lo que llegue por encima se reparte con una regla fija.

Sheet Presupuesto
B1: Presupuesto detallado
B2: Cada gasto con su valor por pago y su frecuencia. Las filas grises son automáticas. "Tipo" indica cómo se paga.
B5: Categoría | C5: Concepto | D5: Valor por pago | E5: Frecuencia | F5: Días que dura | G5: Veces al año | H5: Total anual | I5: Promedio mensual | J5: Tipo | K5: Bolsillo | L5: ¿Esencial? | M5: Nota
B6: Deudas | C6: Cuotas mínimas de deudas (hoja Deudas) | D6: =Deudas!$F$21 -> 0 | E6: Mensual | G6: =IF(E6="","",IF(E6="Por duración (días)",IF(N(F6)>0,365/F6,0),IF(E6="Meses con seguridad social",Ingresos!$S$17,IFERROR(VLOOKUP(E6,Listas!$C$2:$D$10,2,FALSE()),0)))) -> 12 | H6: =IF(OR(N(D6)=0,G6=""),0,D6*G6) -> 0 | I6: =H6/12 -> 0 | J6: Deuda | L6: Sí | M6: Automático: no editar.
B7: Seguros | C7: Primas de seguros nuevos (hoja Seguros) | D7: =Seguros!$H$16 -> 0 | E7: Anual | G7: =IF(E7="","",IF(E7="Por duración (días)",IF(N(F7)>0,365/F7,0),IF(E7="Meses con seguridad social",Ingresos!$S$17,IFERROR(VLOOKUP(E7,Listas!$C$2:$D$10,2,FALSE()),0)))) -> 1 | H7: =IF(OR(N(D7)=0,G7=""),0,D7*G7) -> 0 | I7: =H7/12 -> 0 | J7: Bolsillo | K7: Seguros | L7: Sí | M7: Automático: no editar.
B8: Metas | C8: =IF(Metas!$B$6="","(Meta sin usar)","Meta: "&Metas!$B$6) -> (Meta sin usar) | D8: =Metas!$K$6 -> 0 | E8: Mensual | G8: =IF(E8="","",IF(E8="Por duración (días)",IF(N(F8)>0,365/F8,0),IF(E8="Meses con seguridad social",Ingresos!$S$17,IFERROR(VLOOKUP(E8,Listas!$C$2:$D$10,2,FALSE()),0)))) -> 12 | H8: =IF(OR(N(D8)=0,G8=""),0,D8*G8) -> 0 | I8: =H8/12 -> 0 | J8: Bolsillo | K8: =IF(Metas!$C$6="","Metas",Metas!$C$6) -> Metas | L8: No | M8: Automático: no editar.
B9: Metas | C9: =IF(Metas!$B$7="","(Meta sin usar)","Meta: "&Metas!$B$7) -> (Meta sin usar) | D9: =Metas!$K$7 -> 0 | E9: Mensual | G9: =IF(E9="","",IF(E9="Por duración (días)",IF(N(F9)>0,365/F9,0),IF(E9="Meses con seguridad social",Ingresos!$S$17,IFERROR(VLOOKUP(E9,Listas!$C$2:$D$10,2,FALSE()),0)))) -> 12 | H9: =IF(OR(N(D9)=0,G9=""),0,D9*G9) -> 0 | I9: =H9/12 -> 0 | J9: Bolsillo | K9: =IF(Metas!$C$7="","Metas",Metas!$C$7) -> Metas | L9: No | M9: Automático: no editar.
B10: Metas | C10: =IF(Metas!$B$8="","(Meta sin usar)","Meta: "&Metas!$B$8) -> (Meta sin usar) | D10: =Metas!$K$8 -> 0 | E10: Mensual | G10: =IF(E10="","",IF(E10="Por duración (días)",IF(N(F10)>0,365/F10,0),IF(E10="Meses con seguridad social",Ingresos!$S$17,IFERROR(VLOOKUP(E10,Listas!$C$2:$D$10,2,FALSE()),0)))) -> 12 | H10: =IF(OR(N(D10)=0,G10=""),0,D10*G10) -> 0 | I10: =H10/12 -> 0 | J10: Bolsillo | K10: =IF(Metas!$C$8="","Metas",Metas!$C$8) -> Metas | L10: No | M10: Automático: no editar.
B11: Metas | C11: =IF(Metas!$B$9="","(Meta sin usar)","Meta: "&Metas!$B$9) -> (Meta sin usar) | D11: =Metas!$K$9 -> 0 | E11: Mensual | G11: =IF(E11="","",IF(E11="Por duración (días)",IF(N(F11)>0,365/F11,0),IF(E11="Meses con seguridad social",Ingresos!$S$17,IFERROR(VLOOKUP(E11,Listas!$C$2:$D$10,2,FALSE()),0)))) -> 12 | H11: =IF(OR(N(D11)=0,G11=""),0,D11*G11) -> 0 | I11: =H11/12 -> 0 | J11: Bolsillo | K11: =IF(Metas!$C$9="","Metas",Metas!$C$9) -> Metas | L11: No | M11: Automático: no editar.
B12: Metas | C12: =IF(Metas!$B$10="","(Meta sin usar)","Meta: "&Metas!$B$10) -> (Meta sin usar) | D12: =Metas!$K$10 -> 0 | E12: Mensual | G12: =IF(E12="","",IF(E12="Por duración (días)",IF(N(F12)>0,365/F12,0),IF(E12="Meses con seguridad social",Ingresos!$S$17,IFERROR(VLOOKUP(E12,Listas!$C$2:$D$10,2,FALSE()),0)))) -> 12 | H12: =IF(OR(N(D12)=0,G12=""),0,D12*G12) -> 0 | I12: =H12/12 -> 0 | J12: Bolsillo | K12: =IF(Metas!$C$10="","Metas",Metas!$C$10) -> Metas | L12: No | M12: Automático: no editar.
B13: Seguridad social | C13: Salud, pensión y ARL (valor por mes de pago) | E13: Meses con seguridad social | G13: =IF(E13="","",IF(E13="Por duración (días)",IF(N(F13)>0,365/F13,0),IF(E13="Meses con seguridad social",Ingresos!$S$17,IFERROR(VLOOKUP(E13,Listas!$C$2:$D$10,2,FALSE()),0)))) -> 12 | H13: =IF(OR(N(D13)=0,G13=""),0,D13*G13) -> 0 | I13: =H13/12 -> 0 | J13: Seg. social | L13: Sí | M13: Los meses de pago se marcan en Ingresos.
B14: Vivienda | C14: Arriendo o cuota de vivienda | E14: Mensual | G14: =IF(E14="","",IF(E14="Por duración (días)",IF(N(F14)>0,365/F14,0),IF(E14="Meses con seguridad social",Ingresos!$S$17,IFERROR(VLOOKUP(E14,Listas!$C$2:$D$10,2,FALSE()),0)))) -> 12 | H14: =IF(OR(N(D14)=0,G14=""),0,D14*G14) -> 0 | I14: =H14/12 -> 0 | J14: Directo | L14: Sí
B15: Vivienda | C15: Administración | E15: Mensual | G15: =IF(E15="","",IF(E15="Por duración (días)",IF(N(F15)>0,365/F15,0),IF(E15="Meses con seguridad social",Ingresos!$S$17,IFERROR(VLOOKUP(E15,Listas!$C$2:$D$10,2,FALSE()),0)))) -> 12 | H15: =IF(OR(N(D15)=0,G15=""),0,D15*G15) -> 0 | I15: =H15/12 -> 0 | J15: Directo | L15: Sí
B16: Vivienda | C16: Servicios públicos | E16: Mensual | G16: =IF(E16="","",IF(E16="Por duración (días)",IF(N(F16)>0,365/F16,0),IF(E16="Meses con seguridad social",Ingresos!$S$17,IFERROR(VLOOKUP(E16,Listas!$C$2:$D$10,2,FALSE()),0)))) -> 12 | H16: =IF(OR(N(D16)=0,G16=""),0,D16*G16) -> 0 | I16: =H16/12 -> 0 | J16: Directo | L16: Sí
B17: Vivienda | C17: Internet y televisión | E17: Mensual | G17: =IF(E17="","",IF(E17="Por duración (días)",IF(N(F17)>0,365/F17,0),IF(E17="Meses con seguridad social",Ingresos!$S$17,IFERROR(VLOOKUP(E17,Listas!$C$2:$D$10,2,FALSE()),0)))) -> 12 | H17: =IF(OR(N(D17)=0,G17=""),0,D17*G17) -> 0 | I17: =H17/12 -> 0 | J17: Directo | L17: Sí
B18: Vivienda | C18: Aseo o empleada doméstica | E18: Mensual | G18: =IF(E18="","",IF(E18="Por duración (días)",IF(N(F18)>0,365/F18,0),IF(E18="Meses con seguridad social",Ingresos!$S$17,IFERROR(VLOOKUP(E18,Listas!$C$2:$D$10,2,FALSE()),0)))) -> 12 | H18: =IF(OR(N(D18)=0,G18=""),0,D18*G18) -> 0 | I18: =H18/12 -> 0 | J18: Directo | L18: No
B19: Vivienda | C19: Mantenimiento del hogar | E19: Mensual | G19: =IF(E19="","",IF(E19="Por duración (días)",IF(N(F19)>0,365/F19,0),IF(E19="Meses con seguridad social",Ingresos!$S$17,IFERROR(VLOOKUP(E19,Listas!$C$2:$D$10,2,FALSE()),0)))) -> 12 | H19: =IF(OR(N(D19)=0,G19=""),0,D19*G19) -> 0 | I19: =H19/12 -> 0 | J19: Directo | L19: No
B20: Impuestos y trámites | C20: Predial | E20: Anual | G20: =IF(E20="","",IF(E20="Por duración (días)",IF(N(F20)>0,365/F20,0),IF(E20="Meses con seguridad social",Ingresos!$S$17,IFERROR(VLOOKUP(E20,Listas!$C$2:$D$10,2,FALSE()),0)))) -> 1 | H20: =IF(OR(N(D20)=0,G20=""),0,D20*G20) -> 0 | I20: =H20/12 -> 0 | J20: Bolsillo | K20: Impuestos y trámites | L20: Sí
B21: Alimentación | C21: Mercado | E21: Semanal | G21: =IF(E21="","",IF(E21="Por duración (días)",IF(N(F21)>0,365/F21,0),IF(E21="Meses con seguridad social",Ingresos!$S$17,IFERROR(VLOOKUP(E21,Listas!$C$2:$D$10,2,FALSE()),0)))) -> 52 | H21: =IF(OR(N(D21)=0,G21=""),0,D21*G21) -> 0 | I21: =H21/12 -> 0 | J21: Directo | L21: Sí
B22: Alimentación | C22: Restaurantes y salidas a comer | E22: Mensual | G22: =IF(E22="","",IF(E22="Por duración (días)",IF(N(F22)>0,365/F22,0),IF(E22="Meses con seguridad social",Ingresos!$S$17,IFERROR(VLOOKUP(E22,Listas!$C$2:$D$10,2,FALSE()),0)))) -> 12 | H22: =IF(OR(N(D22)=0,G22=""),0,D22*G22) -> 0 | I22: =H22/12 -> 0 | J22: Directo | L22: No
B23: Alimentación | C23: Domicilios | E23: Mensual | G23: =IF(E23="","",IF(E23="Por duración (días)",IF(N(F23)>0,365/F23,0),IF(E23="Meses con seguridad social",Ingresos!$S$17,IFERROR(VLOOKUP(E23,Listas!$C$2:$D$10,2,FALSE()),0)))) -> 12 | H23: =IF(OR(N(D23)=0,G23=""),0,D23*G23) -> 0 | I23: =H23/12 -> 0 | J23: Directo | L23: No
B24: Transporte | C24: Gasolina | E24: Mensual | G24: =IF(E24="","",IF(E24="Por duración (días)",IF(N(F24)>0,365/F24,0),IF(E24="Meses con seguridad social",Ingresos!$S$17,IFERROR(VLOOKUP(E24,Listas!$C$2:$D$10,2,FALSE()),0)))) -> 12 | H24: =IF(OR(N(D24)=0,G24=""),0,D24*G24) -> 0 | I24: =H24/12 -> 0 | J24: Directo | L24: Sí
B25: Transporte | C25: Parqueadero y peajes | E25: Mensual | G25: =IF(E25="","",IF(E25="Por duración (días)",IF(N(F25)>0,365/F25,0),IF(E25="Meses con seguridad social",Ingresos!$S$17,IFERROR(VLOOKUP(E25,Listas!$C$2:$D$10,2,FALSE()),0)))) -> 12 | H25: =IF(OR(N(D25)=0,G25=""),0,D25*G25) -> 0 | I25: =H25/12 -> 0 | J25: Directo | L25: No
B26: Transporte | C26: Transporte público y apps | E26: Mensual | G26: =IF(E26="","",IF(E26="Por duración (días)",IF(N(F26)>0,365/F26,0),IF(E26="Meses con seguridad social",Ingresos!$S$17,IFERROR(VLOOKUP(E26,Listas!$C$2:$D$10,2,FALSE()),0)))) -> 12 | H26: =IF(OR(N(D26)=0,G26=""),0,D26*G26) -> 0 | I26: =H26/12 -> 0 | J26: Directo | L26: Sí
B27: Transporte | C27: SOAT | E27: Anual | G27: =IF(E27="","",IF(E27="Por duración (días)",IF(N(F27)>0,365/F27,0),IF(E27="Meses con seguridad social",Ingresos!$S$17,IFERROR(VLOOKUP(E27,Listas!$C$2:$D$10,2,FALSE()),0)))) -> 1 | H27: =IF(OR(N(D27)=0,G27=""),0,D27*G27) -> 0 | I27: =H27/12 -> 0 | J27: Bolsillo | K27: Vehículo | L27: Sí
B28: Transporte | C28: Seguro del carro | E28: Anual | G28: =IF(E28="","",IF(E28="Por duración (días)",IF(N(F28)>0,365/F28,0),IF(E28="Meses con seguridad social",Ingresos!$S$17,IFERROR(VLOOKUP(E28,Listas!$C$2:$D$10,2,FALSE()),0)))) -> 1 | H28: =IF(OR(N(D28)=0,G28=""),0,D28*G28) -> 0 | I28: =H28/12 -> 0 | J28: Bolsillo | K28: Vehículo | L28: Sí | M28: Seguros que ya existen van aquí, no en la hoja Seguros.
B29: Transporte | C29: Mantenimiento del carro | E29: Semestral | G29: =IF(E29="","",IF(E29="Por duración (días)",IF(N(F29)>0,365/F29,0),IF(E29="Meses con seguridad social",Ingresos!$S$17,IFERROR(VLOOKUP(E29,Listas!$C$2:$D$10,2,FALSE()),0)))) -> 2 | H29: =IF(OR(N(D29)=0,G29=""),0,D29*G29) -> 0 | I29: =H29/12 -> 0 | J29: Bolsillo | K29: Vehículo | L29: No
B30: Impuestos y trámites | C30: Impuesto vehicular | E30: Anual | G30: =IF(E30="","",IF(E30="Por duración (días)",IF(N(F30)>0,365/F30,0),IF(E30="Meses con seguridad social",Ingresos!$S$17,IFERROR(VLOOKUP(E30,Listas!$C$2:$D$10,2,FALSE()),0)))) -> 1 | H30: =IF(OR(N(D30)=0,G30=""),0,D30*G30) -> 0 | I30: =H30/12 -> 0 | J30: Bolsillo | K30: Impuestos y trámites | L30: Sí
B31: Salud y bienestar | C31: Medicina prepagada o plan complementario | E31: Mensual | G31: =IF(E31="","",IF(E31="Por duración (días)",IF(N(F31)>0,365/F31,0),IF(E31="Meses con seguridad social",Ingresos!$S$17,IFERROR(VLOOKUP(E31,Listas!$C$2:$D$10,2,FALSE()),0)))) -> 12 | H31: =IF(OR(N(D31)=0,G31=""),0,D31*G31) -> 0 | I31: =H31/12 -> 0 | J31: Directo | L31: Sí
B32: Salud y bienestar | C32: Droguería | E32: Mensual | G32: =IF(E32="","",IF(E32="Por duración (días)",IF(N(F32)>0,365/F32,0),IF(E32="Meses con seguridad social",Ingresos!$S$17,IFERROR(VLOOKUP(E32,Listas!$C$2:$D$10,2,FALSE()),0)))) -> 12 | H32: =IF(OR(N(D32)=0,G32=""),0,D32*G32) -> 0 | I32: =H32/12 -> 0 | J32: Directo | L32: Sí
B33: Salud y bienestar | C33: Terapias o psicología | E33: Mensual | G33: =IF(E33="","",IF(E33="Por duración (días)",IF(N(F33)>0,365/F33,0),IF(E33="Meses con seguridad social",Ingresos!$S$17,IFERROR(VLOOKUP(E33,Listas!$C$2:$D$10,2,FALSE()),0)))) -> 12 | H33: =IF(OR(N(D33)=0,G33=""),0,D33*G33) -> 0 | I33: =H33/12 -> 0 | J33: Directo | L33: No
B34: Salud y bienestar | C34: Gimnasio | E34: Mensual | G34: =IF(E34="","",IF(E34="Por duración (días)",IF(N(F34)>0,365/F34,0),IF(E34="Meses con seguridad social",Ingresos!$S$17,IFERROR(VLOOKUP(E34,Listas!$C$2:$D$10,2,FALSE()),0)))) -> 12 | H34: =IF(OR(N(D34)=0,G34=""),0,D34*G34) -> 0 | I34: =H34/12 -> 0 | J34: Directo | L34: No | M34: Si se paga anual, cambia la frecuencia y el tipo a Bolsillo.
B35: Salud y bienestar | C35: Suplementos | E35: Por duración (días) | G35: =IF(E35="","",IF(E35="Por duración (días)",IF(N(F35)>0,365/F35,0),IF(E35="Meses con seguridad social",Ingresos!$S$17,IFERROR(VLOOKUP(E35,Listas!$C$2:$D$10,2,FALSE()),0)))) -> 0 | H35: =IF(OR(N(D35)=0,G35=""),0,D35*G35) -> 0 | I35: =H35/12 -> 0 | J35: Bolsillo | K35: Salud y cuidado | L35: No | M35: Escribe los días que dura el frasco.
B36: Cuidado personal | C36: Peluquería y uñas | E36: Mensual | G36: =IF(E36="","",IF(E36="Por duración (días)",IF(N(F36)>0,365/F36,0),IF(E36="Meses con seguridad social",Ingresos!$S$17,IFERROR(VLOOKUP(E36,Listas!$C$2:$D$10,2,FALSE()),0)))) -> 12 | H36: =IF(OR(N(D36)=0,G36=""),0,D36*G36) -> 0 | I36: =H36/12 -> 0 | J36: Directo | L36: No
B37: Cuidado personal | C37: Skincare | E37: Cada 4 meses | G37: =IF(E37="","",IF(E37="Por duración (días)",IF(N(F37)>0,365/F37,0),IF(E37="Meses con seguridad social",Ingresos!$S$17,IFERROR(VLOOKUP(E37,Listas!$C$2:$D$10,2,FALSE()),0)))) -> 3 | H37: =IF(OR(N(D37)=0,G37=""),0,D37*G37) -> 0 | I37: =H37/12 -> 0 | J37: Bolsillo | K37: Salud y cuidado | L37: No
B38: Cuidado personal | C38: Ropa y calzado | E38: Anual | G38: =IF(E38="","",IF(E38="Por duración (días)",IF(N(F38)>0,365/F38,0),IF(E38="Meses con seguridad social",Ingresos!$S$17,IFERROR(VLOOKUP(E38,Listas!$C$2:$D$10,2,FALSE()),0)))) -> 1 | H38: =IF(OR(N(D38)=0,G38=""),0,D38*G38) -> 0 | I38: =H38/12 -> 0 | J38: Bolsillo | K38: Ropa | L38: No
B39: Hijos y familia | C39: Colegio o universidad (mensualidad) | E39: Mensual | G39: =IF(E39="","",IF(E39="Por duración (días)",IF(N(F39)>0,365/F39,0),IF(E39="Meses con seguridad social",Ingresos!$S$17,IFERROR(VLOOKUP(E39,Listas!$C$2:$D$10,2,FALSE()),0)))) -> 12 | H39: =IF(OR(N(D39)=0,G39=""),0,D39*G39) -> 0 | I39: =H39/12 -> 0 | J39: Directo | L39: Sí
B40: Hijos y familia | C40: Matrículas y útiles | E40: Anual | G40: =IF(E40="","",IF(E40="Por duración (días)",IF(N(F40)>0,365/F40,0),IF(E40="Meses con seguridad social",Ingresos!$S$17,IFERROR(VLOOKUP(E40,Listas!$C$2:$D$10,2,FALSE()),0)))) -> 1 | H40: =IF(OR(N(D40)=0,G40=""),0,D40*G40) -> 0 | I40: =H40/12 -> 0 | J40: Bolsillo | K40: Educación | L40: Sí
B41: Hijos y familia | C41: Gastos y mesadas de hijos | E41: Mensual | G41: =IF(E41="","",IF(E41="Por duración (días)",IF(N(F41)>0,365/F41,0),IF(E41="Meses con seguridad social",Ingresos!$S$17,IFERROR(VLOOKUP(E41,Listas!$C$2:$D$10,2,FALSE()),0)))) -> 12 | H41: =IF(OR(N(D41)=0,G41=""),0,D41*G41) -> 0 | I41: =H41/12 -> 0 | J41: Directo | L41: Sí
B42: Hijos y familia | C42: Ayudas a familiares | E42: Mensual | G42: =IF(E42="","",IF(E42="Por duración (días)",IF(N(F42)>0,365/F42,0),IF(E42="Meses con seguridad social",Ingresos!$S$17,IFERROR(VLOOKUP(E42,Listas!$C$2:$D$10,2,FALSE()),0)))) -> 12 | H42: =IF(OR(N(D42)=0,G42=""),0,D42*G42) -> 0 | I42: =H42/12 -> 0 | J42: Directo | L42: No
...

Sheet Deudas
B1: Deudas
B2: Inventario, orden de pago y simulación mes a mes. El pago extra sale del sobrante (hoja Flujo anual). Para el seguimiento mensual de cada crédito usa la plantilla de créditos.
B5: Parámetros
B6: Método de pago | C6: Avalancha | D6: Avalancha: mayor tasa primero (ahorra más). Bola de nieve: menor saldo primero (motiva más).
B7: Umbral de deuda cara | C7: =Supuestos!$C$22 -> 0.2
B8: Pago extra mensual (desde el sobrante) | C8: ='Flujo anual'!$Q$34/12 -> 0
B9: Pago mensual total para deudas | C9: =F21+C8 -> 0
B10: Abono único inicial (desde el excedente) | C10: =Bolsillos!$C$26 -> 0
B11: Primer mes de la simulación | C11: =DATE(YEAR(Supuestos!$C$12),MONTH(Supuestos!$C$12)+1,1) -> 46296
B12: Deuda | C12: Tipo | D12: Saldo | E12: Tasa EA | F12: Cuota mínima mensual | G12: ¿Acepta abonos extra? | H12: Abonos extra desde | I12: Tasa mensual | J12: ¿Deuda cara? | K12: Orden de pago | L12: Meses para pagar | M12: Fecha de salida | N12: Intereses con el plan | O12: Intereses solo con la cuota (aprox.) | P12: Aux.
G13: Sí | I13: =IF(E13="","",(1+E13)^(1/12)-1) | J13: =IF(N(D13)<=0,"",IF(N(E13)>=$C$7,"Sí","No")) | K13: =IF(N(D13)<=0,"",IF($C$6="Bola de nieve",1+COUNTIFS($D$13:$D$20,">0",$D$13:$D$20,"<"&D13)+COUNTIFS($D$13:$D$20,D13,$P$13:$P$20,"<"&P13),1+COUNTIFS($D$13:$D$20,">0",$E$13:$E$20,">"&N(E13))+COUNTIFS($D$13:$D$20,">0",$E$13:$E$20,N(E13),$P$13:$P$20,"<"&P13))) | L13: =IF(K13="","",INDEX($E$86:$E$93,K13)) | M13: =IF(OR(L13="",NOT(ISNUMBER(L13))),"",IF(L13=0,$C$11,EDATE($C$11,L13-1))) | N13: =IF(K13="","",INDEX($F$86:$F$93,K13)) | O13: =IF(N(D13)<=0,"",IF(N(E13)=0,0,IFERROR(IF(N(F13)<=D13*I13,"No se paga",F13*NPER(I13,-F13,D13)-D13),"No se paga"))) | P13: =ROW() -> 13
G14: Sí | I14: =IF(E14="","",(1+E14)^(1/12)-1) | J14: =IF(N(D14)<=0,"",IF(N(E14)>=$C$7,"Sí","No")) | K14: =IF(N(D14)<=0,"",IF($C$6="Bola de nieve",1+COUNTIFS($D$13:$D$20,">0",$D$13:$D$20,"<"&D14)+COUNTIFS($D$13:$D$20,D14,$P$13:$P$20,"<"&P14),1+COUNTIFS($D$13:$D$20,">0",$E$13:$E$20,">"&N(E14))+COUNTIFS($D$13:$D$20,">0",$E$13:$E$20,N(E14),$P$13:$P$20,"<"&P14))) | L14: =IF(K14="","",INDEX($E$86:$E$93,K14)) | M14: =IF(OR(L14="",NOT(ISNUMBER(L14))),"",IF(L14=0,$C$11,EDATE($C$11,L14-1))) | N14: =IF(K14="","",INDEX($F$86:$F$93,K14)) | O14: =IF(N(D14)<=0,"",IF(N(E14)=0,0,IFERROR(IF(N(F14)<=D14*I14,"No se paga",F14*NPER(I14,-F14,D14)-D14),"No se paga"))) | P14: =ROW() -> 14
G15: Sí | I15: =IF(E15="","",(1+E15)^(1/12)-1) | J15: =IF(N(D15)<=0,"",IF(N(E15)>=$C$7,"Sí","No")) | K15: =IF(N(D15)<=0,"",IF($C$6="Bola de nieve",1+COUNTIFS($D$13:$D$20,">0",$D$13:$D$20,"<"&D15)+COUNTIFS($D$13:$D$20,D15,$P$13:$P$20,"<"&P15),1+COUNTIFS($D$13:$D$20,">0",$E$13:$E$20,">"&N(E15))+COUNTIFS($D$13:$D$20,">0",$E$13:$E$20,N(E15),$P$13:$P$20,"<"&P15))) | L15: =IF(K15="","",INDEX($E$86:$E$93,K15)) | M15: =IF(OR(L15="",NOT(ISNUMBER(L15))),"",IF(L15=0,$C$11,EDATE($C$11,L15-1))) | N15: =IF(K15="","",INDEX($F$86:$F$93,K15)) | O15: =IF(N(D15)<=0,"",IF(N(E15)=0,0,IFERROR(IF(N(F15)<=D15*I15,"No se paga",F15*NPER(I15,-F15,D15)-D15),"No se paga"))) | P15: =ROW() -> 15
G16: Sí | I16: =IF(E16="","",(1+E16)^(1/12)-1) | J16: =IF(N(D16)<=0,"",IF(N(E16)>=$C$7,"Sí","No")) | K16: =IF(N(D16)<=0,"",IF($C$6="Bola de nieve",1+COUNTIFS($D$13:$D$20,">0",$D$13:$D$20,"<"&D16)+COUNTIFS($D$13:$D$20,D16,$P$13:$P$20,"<"&P16),1+COUNTIFS($D$13:$D$20,">0",$E$13:$E$20,">"&N(E16))+COUNTIFS($D$13:$D$20,">0",$E$13:$E$20,N(E16),$P$13:$P$20,"<"&P16))) | L16: =IF(K16="","",INDEX($E$86:$E$93,K16)) | M16: =IF(OR(L16="",NOT(ISNUMBER(L16))),"",IF(L16=0,$C$11,EDATE($C$11,L16-1))) | N16: =IF(K16="","",INDEX($F$86:$F$93,K16)) | O16: =IF(N(D16)<=0,"",IF(N(E16)=0,0,IFERROR(IF(N(F16)<=D16*I16,"No se paga",F16*NPER(I16,-F16,D16)-D16),"No se paga"))) | P16: =ROW() -> 16
G17: Sí | I17: =IF(E17="","",(1+E17)^(1/12)-1) | J17: =IF(N(D17)<=0,"",IF(N(E17)>=$C$7,"Sí","No")) | K17: =IF(N(D17)<=0,"",IF($C$6="Bola de nieve",1+COUNTIFS($D$13:$D$20,">0",$D$13:$D$20,"<"&D17)+COUNTIFS($D$13:$D$20,D17,$P$13:$P$20,"<"&P17),1+COUNTIFS($D$13:$D$20,">0",$E$13:$E$20,">"&N(E17))+COUNTIFS($D$13:$D$20,">0",$E$13:$E$20,N(E17),$P$13:$P$20,"<"&P17))) | L17: =IF(K17="","",INDEX($E$86:$E$93,K17)) | M17: =IF(OR(L17="",NOT(ISNUMBER(L17))),"",IF(L17=0,$C$11,EDATE($C$11,L17-1))) | N17: =IF(K17="","",INDEX($F$86:$F$93,K17)) | O17: =IF(N(D17)<=0,"",IF(N(E17)=0,0,IFERROR(IF(N(F17)<=D17*I17,"No se paga",F17*NPER(I17,-F17,D17)-D17),"No se paga"))) | P17: =ROW() -> 17
G18: Sí | I18: =IF(E18="","",(1+E18)^(1/12)-1) | J18: =IF(N(D18)<=0,"",IF(N(E18)>=$C$7,"Sí","No")) | K18: =IF(N(D18)<=0,"",IF($C$6="Bola de nieve",1+COUNTIFS($D$13:$D$20,">0",$D$13:$D$20,"<"&D18)+COUNTIFS($D$13:$D$20,D18,$P$13:$P$20,"<"&P18),1+COUNTIFS($D$13:$D$20,">0",$E$13:$E$20,">"&N(E18))+COUNTIFS($D$13:$D$20,">0",$E$13:$E$20,N(E18),$P$13:$P$20,"<"&P18))) | L18: =IF(K18="","",INDEX($E$86:$E$93,K18)) | M18: =IF(OR(L18="",NOT(ISNUMBER(L18))),"",IF(L18=0,$C$11,EDATE($C$11,L18-1))) | N18: =IF(K18="","",INDEX($F$86:$F$93,K18)) | O18: =IF(N(D18)<=0,"",IF(N(E18)=0,0,IFERROR(IF(N(F18)<=D18*I18,"No se paga",F18*NPER(I18,-F18,D18)-D18),"No se paga"))) | P18: =ROW() -> 18
G19: Sí | I19: =IF(E19="","",(1+E19)^(1/12)-1) | J19: =IF(N(D19)<=0,"",IF(N(E19)>=$C$7,"Sí","No")) | K19: =IF(N(D19)<=0,"",IF($C$6="Bola de nieve",1+COUNTIFS($D$13:$D$20,">0",$D$13:$D$20,"<"&D19)+COUNTIFS($D$13:$D$20,D19,$P$13:$P$20,"<"&P19),1+COUNTIFS($D$13:$D$20,">0",$E$13:$E$20,">"&N(E19))+COUNTIFS($D$13:$D$20,">0",$E$13:$E$20,N(E19),$P$13:$P$20,"<"&P19))) | L19: =IF(K19="","",INDEX($E$86:$E$93,K19)) | M19: =IF(OR(L19="",NOT(ISNUMBER(L19))),"",IF(L19=0,$C$11,EDATE($C$11,L19-1))) | N19: =IF(K19="","",INDEX($F$86:$F$93,K19)) | O19: =IF(N(D19)<=0,"",IF(N(E19)=0,0,IFERROR(IF(N(F19)<=D19*I19,"No se paga",F19*NPER(I19,-F19,D19)-D19),"No se paga"))) | P19: =ROW() -> 19
G20: Sí | I20: =IF(E20="","",(1+E20)^(1/12)-1) | J20: =IF(N(D20)<=0,"",IF(N(E20)>=$C$7,"Sí","No")) | K20: =IF(N(D20)<=0,"",IF($C$6="Bola de nieve",1+COUNTIFS($D$13:$D$20,">0",$D$13:$D$20,"<"&D20)+COUNTIFS($D$13:$D$20,D20,$P$13:$P$20,"<"&P20),1+COUNTIFS($D$13:$D$20,">0",$E$13:$E$20,">"&N(E20))+COUNTIFS($D$13:$D$20,">0",$E$13:$E$20,N(E20),$P$13:$P$20,"<"&P20))) | L20: =IF(K20="","",INDEX($E$86:$E$93,K20)) | M20: =IF(OR(L20="",NOT(ISNUMBER(L20))),"",IF(L20=0,$C$11,EDATE($C$11,L20-1))) | N20: =IF(K20="","",INDEX($F$86:$F$93,K20)) | O20: =IF(N(D20)<=0,"",IF(N(E20)=0,0,IFERROR(IF(N(F20)<=D20*I20,"No se paga",F20*NPER(I20,-F20,D20)-D20),"No se paga"))) | P20: =ROW() -> 20
B21: Total | D21: =SUM(D13:D20) -> 0 | F21: =SUM(F13:F20) -> 0 | N21: =SUM(N13:N20) -> 0 | O21: =SUM(O13:O20) -> 0
B22: Saldo en deuda cara | C22: =SUMIFS(D13:D20,J13:J20,"Sí") -> 0 | E22: Ahorro en intereses con el plan | H22: =IF(OR(COUNTIF(O13:O20,"No se paga")>0,COUNTIF(L13:L20,"Más de 120")>0),"Ver detalle",SUMIFS(O13:O20,K13:K20,">0")-N21) -> 0
B23: ¿Hay deuda cara? | C23: =IF(C22>0,"Sí","No") -> No | E23: "No acepta abonos" o "desde": créditos con cobertura FRECH, préstamos familiares sin interés o con penalidad por prepago. El extra pasa al siguiente en la lista.
B24: Carga de deuda (cuotas / ingreso mensual) | C24: =IF(Ingresos!$U$14=0,"",F21/Ingresos!$U$14) | E24: Intereses solo con la cuota: cálculo aproximado si nunca se hicieran abonos extra.
B25: Fecha de salida de la deuda cara | C25: =IF(C22=0,"",IF(COUNTIFS(J13:J20,"Sí",L13:L20,"Más de 120")>0,"Más de 120 meses",_xlfn.MAXIFS(M13:M20,J13:J20,"Sí")))
B26: ¿Alguna deuda tarda más de 120 meses? | C26: =IF(COUNTIF(L13:L20,"Más de 120")>0,"Sí","No") -> No
B28: Simulación mes a mes (orden de pago; el pago total se mantiene y lo liberado pasa a la siguiente deuda que acepte abonos)
B29: Mes | E29: =EDATE($C$11,0) -> 46296 | F29: =EDATE($C$11,1) -> 46327 | G29: =EDATE($C$11,2) -> 46357 | H29: =EDATE($C$11,3) -> 46388 | I29: =EDATE($C$11,4) -> 46419 | J29: =EDATE($C$11,5) -> 46447 | K29: =EDATE($C$11,6) -> 46478 | L29: =EDATE($C$11,7) -> 46508 | M29: =EDATE($C$11,8) -> 46539 | N29: =EDATE($C$11,9) -> 46569 | O29: =EDATE($C$11,10) -> 46600 | P29: =EDATE($C$11,11) -> 46631 | Q29: =EDATE($C$11,12) -> 46661 | R29: =EDATE($C$11,13) -> 46692 | S29: =EDATE($C$11,14) -> 46722 | T29: =EDATE($C$11,15) -> 46753 | U29: =EDATE($C$11,16) -> 46784 | V29: =EDATE($C$11,17) -> 46813 | W29: =EDATE($C$11,18) -> 46844 | X29: =EDATE($C$11,19) -> 46874 | Y29: =EDATE($C$11,20) -> 46905 | Z29: =EDATE($C$11,21) -> 46935 | AA29: =EDATE($C$11,22) -> 46966 | AB29: =EDATE($C$11,23) -> 46997 | AC29: =EDATE($C$11,24) -> 47027 | AD29: =EDATE($C$11,25) -> 47058 | AE29: =EDATE($C$11,26) -> 47088 | AF29: =EDATE($C$11,27) -> 47119 | AG29: =EDATE($C$11,28) -> 47150 | AH29: =EDATE($C$11,29) -> 47178 | AI29: =EDATE($C$11,30) -> 47209 | AJ29: =EDATE($C$11,31) -> 47239 | AK29: =EDATE($C$11,32) -> 47270 | AL29: =EDATE($C$11,33) -> 47300 | AM29: =EDATE($C$11,34) -> 47331 | AN29: =EDATE($C$11,35) -> 47362 | AO29: =EDATE($C$11,36) -> 47392 | AP29: =EDATE($C$11,37) -> 47423 | AQ29: =EDATE($C$11,38) -> 47453 | AR29: =EDATE($C$11,39) -> 47484 | AS29: =EDATE($C$11,40) -> 47515 | AT29: =EDATE($C$11,41) -> 47543 | AU29: =EDATE($C$11,42) -> 47574 | AV29: =EDATE($C$11,43) -> 47604 | AW29: =EDATE($C$11,44) -> 47635 | AX29: =EDATE($C$11,45) -> 47665 | AY29: =EDATE($C$11,46) -> 47696 | AZ29: =EDATE($C$11,47) -> 47727 | BA29: =EDATE($C$11,48) -> 47757 | BB29: =EDATE($C$11,49) -> 47788 | BC29: =EDATE($C$11,50) -> 47818 | BD29: =EDATE($C$11,51) -> 47849 | BE29: =EDATE($C$11,52) -> 47880 | BF29: =EDATE($C$11,53) -> 47908 | BG29: =EDATE($C$11,54) -> 47939 | BH29: =EDATE($C$11,55) -> 47969 | BI29: =EDATE($C$11,56) -> 48000 | BJ29: =EDATE($C$11,57) -> 48030 | BK29: =EDATE($C$11,58) -> 48061 | BL29: =EDATE($C$11,59) -> 48092 | BM29: =EDATE($C$11,60) -> 48122 | BN29: =EDATE($C$11,61) -> 48153 | BO29: =EDATE($C$11,62) -> 48183 | BP29: =EDATE($C$11,63) -> 48214 | BQ29: =EDATE($C$11,64) -> 48245 | BR29: =EDATE($C$11,65) -> 48274 | BS29: =EDATE($C$11,66) -> 48305 | BT29: =EDATE($C$11,67) -> 48335 | BU29: =EDATE($C$11,68) -> 48366 | BV29: =EDATE($C$11,69) -> 48396 | BW29: =EDATE($C$11,70) -> 48427 | BX29: =EDATE($C$11,71) -> 48458 | BY29: =EDATE($C$11,72) -> 48488 | BZ29: =EDATE($C$11,73) -> 48519 | CA29: =EDATE($C$11,74) -> 48549 | CB29: =EDATE($C$11,75) -> 48580 | CC29: =EDATE($C$11,76) -> 48611 | CD29: =EDATE($C$11,77) -> 48639 | CE29: =EDATE($C$11,78) -> 48670 | CF29: =EDATE($C$11,79) -> 48700 | CG29: =EDATE($C$11,80) -> 48731 | CH29: =EDATE($C$11,81) -> 48761 | CI29: =EDATE($C$11,82) -> 48792 | CJ29: =EDATE($C$11,83) -> 48823 | CK29: =EDATE($C$11,84) -> 48853 | CL29: =EDATE($C$11,85) -> 48884 | CM29: =EDATE($C$11,86) -> 48914 | CN29: =EDATE($C$11,87) -> 48945 | CO29: =EDATE($C$11,88) -> 48976 | CP29: =EDATE($C$11,89) -> 49004 | CQ29: =EDATE($C$11,90) -> 49035 | CR29: =EDATE($C$11,91) -> 49065 | CS29: =EDATE($C$11,92) -> 49096 | CT29: =EDATE($C$11,93) -> 49126 | CU29: =EDATE($C$11,94) -> 49157 | CV29: =EDATE($C$11,95) -> 49188 | CW29: =EDATE($C$11,96) -> 49218 | CX29: =EDATE($C$11,97) -> 49249 | CY29: =EDATE($C$11,98) -> 49279 | CZ29: =EDATE($C$11,99) -> 49310 | DA29: =EDATE($C$11,100) -> 49341 | DB29: =EDATE($C$11,101) -> 49369 | DC29: =EDATE($C$11,102) -> 49400 | DD29: =EDATE($C$11,103) -> 49430 | DE29: =EDATE($C$11,104) -> 49461 | DF29: =EDATE($C$11,105) -> 49491 | DG29: =EDATE($C$11,106) -> 49522 | DH29: =EDATE($C$11,107) -> 49553 | DI29: =EDATE($C$11,108) -> 49583 | DJ29: =EDATE($C$11,109) -> 49614 | DK29: =EDATE($C$11,110) -> 49644 | DL29: =EDATE($C$11,111) -> 49675 | DM29: =EDATE($C$11,112) -> 49706 | DN29: =EDATE($C$11,113) -> 49735 | DO29: =EDATE($C$11,114) -> 49766 | DP29: =EDATE($C$11,115) -> 49796 | DQ29: =EDATE($C$11,116) -> 49827 | DR29: =EDATE($C$11,117) -> 49857 | DS29: =EDATE($C$11,118) -> 49888 | DT29: =EDATE($C$11,119) -> 49919
B30: Pago total disponible | E30: =$C$9 -> 0 | F30: =$C$9 -> 0 | G30: =$C$9 -> 0 | H30: =$C$9 -> 0 | I30: =$C$9 -> 0 | J30: =$C$9 -> 0 | K30: =$C$9 -> 0 | L30: =$C$9 -> 0 | ... DT30: =$C$9 -> 0
B31: Disponible para abono extra | E31: =E30-(E35+E41+E47+E53+E59+E65+E71+E77) -> 0 | F31: =F30-(F35+F41+F47+F53+F59+F65+F71+F77) -> 0 | G31: =G30-(G35+G41+G47+G53+G59+G65+G71+G77) -> 0 | H31: =H30-(H35+H41+H47+H53+H59+H65+H71+H77) -> 0 | I31: =I30-(I35+I41+I47+I53+I59+I65+I71+I77) -> 0 | J31: =J30-(J35+J41+J47+J53+J59+J65+J71+J77) -> 0 | K31: =K30-(K35+K41+K47+K53+K59+K65+K71+K77) -> 0 | L31: =L30-(L35+L41+L47+L53+L59+L65+L71+L77) -> 0 | ... DT31: =DT30-(DT35+DT41+DT47+DT53+DT59+DT65+DT71+DT77) -> 0
B33: ="Orden 1: "&D33 -> Orden 1: (sin deuda) | C33: =IFERROR(MATCH(1,$K$13:$K$20,0),0) -> 0 | D33: =IF(C33=0,"(sin deuda)",INDEX($B$13:$B$20,C33)) -> (sin deuda)
B34: Debe con interés | C34: =IF(C33=0,0,N(INDEX($I$13:$I$20,C33))) -> 0 | E34: =D37*(1+$C$34) -> 0 | F34: =E37*(1+$C$34) -> 0 | G34: =F37*(1+$C$34) -> 0 | H34: =G37*(1+$C$34) -> 0 | I34: =H37*(1+$C$34) -> 0 | J34: =I37*(1+$C$34) -> 0 | K34: =J37*(1+$C$34) -> 0 | L34: =K37*(1+$C$34) -> 0 | ... DT34: =DS37*(1+$C$34) -> 0
B35: Pago mínimo aplicado | C35: =IF(C33=0,0,N(INDEX($F$13:$F$20,C33))) -> 0 | E35: =MIN($C$35,E34) -> 0 | F35: =MIN($C$35,F34) -> 0 | G35: =MIN($C$35,G34) -> 0 | H35: =MIN($C$35,H34) -> 0 | I35: =MIN($C$35,I34) -> 0 | J35: =MIN($C$35,J34) -> 0 | K35: =MIN($C$35,K34) -> 0 | L35: =MIN($C$35,L34) -> 0 | ... DT35: =MIN($C$35,DT34) -> 0
B36: Abono extra | C36: =IF(C33=0,0,IF(INDEX($G$13:$G$20,C33)="No",0,1)) -> 0 | D36: =IF(C33=0,"",IF(N(INDEX($H$13:$H$20,C33))=0,"",INDEX($H$13:$H$20,C33))) | E36: =IF(AND($C$36=1,OR($D$36="",E$29>=$D$36)),MAX(0,MIN(E34-E35,E$31-(0))),0) -> 0 | F36: =IF(AND($C$36=1,OR($D$36="",F$29>=$D$36)),MAX(0,MIN(F34-F35,F$31-(0))),0) -> 0 | G36: =IF(AND($C$36=1,OR($D$36="",G$29>=$D$36)),MAX(0,MIN(G34-G35,G$31-(0))),0) -> 0 | H36: =IF(AND($C$36=1,OR($D$36="",H$29>=$D$36)),MAX(0,MIN(H34-H35,H$31-(0))),0) -> 0 | I36: =IF(AND($C$36=1,OR($D$36="",I$29>=$D$36)),MAX(0,MIN(I34-I35,I$31-(0))),0) -> 0 | J36: =IF(AND($C$36=1,OR($D$36="",J$29>=$D$36)),MAX(0,MIN(J34-J35,J$31-(0))),0) -> 0 | K36: =IF(AND($C$36=1,OR($D$36="",K$29>=$D$36)),MAX(0,MIN(K34-K35,K$31-(0))),0) -> 0 | L36: =IF(AND($C$36=1,OR($D$36="",L$29>=$D$36)),MAX(0,MIN(L34-L35,L$31-(0))),0) -> 0 | ... DT36: =IF(AND($C$36=1,OR($D$36="",DT$29>=$D$36)),MAX(0,MIN(DT34-DT35,DT$31-(0))),0) -> 0
B37: Saldo | C37: inicial | D37: =IF($C$38=0,D38,MAX(0,D38-MAX(0,$C$10-(0)))) -> 0 | E37: =E34-E35-E36 -> 0 | F37: =F34-F35-F36 -> 0 | G37: =G34-G35-G36 -> 0 | H37: =H34-H35-H36 -> 0 | I37: =I34-I35-I36 -> 0 | J37: =J34-J35-J36 -> 0 | K37: =K34-K35-K36 -> 0 | L37: =L34-L35-L36 -> 0 | ... DT37: =DT34-DT35-DT36 -> 0
C38: =IF(AND(C36=1,OR(D36="",D36<=$C$11)),1,0) -> 0 | D38: =IF(C33=0,0,N(INDEX($D$13:$D$20,C33))) -> 0
B39: ="Orden 2: "&D39 -> Orden 2: (sin deuda) | C39: =IFERROR(MATCH(2,$K$13:$K$20,0),0) -> 0 | D39: =IF(C39=0,"(sin deuda)",INDEX($B$13:$B$20,C39)) -> (sin deuda)
B40: Debe con interés | C40: =IF(C39=0,0,N(INDEX($I$13:$I$20,C39))) -> 0 | E40: =D43*(1+$C$40) -> 0 | F40: =E43*(1+$C$40) -> 0 | G40: =F43*(1+$C$40) -> 0 | H40: =G43*(1+$C$40) -> 0 | I40: =H43*(1+$C$40) -> 0 | J40: =I43*(1+$C$40) -> 0 | K40: =J43*(1+$C$40) -> 0 | L40: =K43*(1+$C$40) -> 0 | ... DT40: =DS43*(1+$C$40) -> 0
B41: Pago mínimo aplicado | C41: =IF(C39=0,0,N(INDEX($F$13:$F$20,C39))) -> 0 | E41: =MIN($C$41,E40) -> 0 | F41: =MIN($C$41,F40) -> 0 | G41: =MIN($C$41,G40) -> 0 | H41: =MIN($C$41,H40) -> 0 | I41: =MIN($C$41,I40) -> 0 | J41: =MIN($C$41,J40) -> 0 | K41: =MIN($C$41,K40) -> 0 | L41: =MIN($C$41,L40) -> 0 | ... DT41: =MIN($C$41,DT40) -> 0
B42: Abono extra | C42: =IF(C39=0,0,IF(INDEX($G$13:$G$20,C39)="No",0,1)) -> 0 | D42: =IF(C39=0,"",IF(N(INDEX($H$13:$H$20,C39))=0,"",INDEX($H$13:$H$20,C39))) | E42: =IF(AND($C$42=1,OR($D$42="",E$29>=$D$42)),MAX(0,MIN(E40-E41,E$31-(E36))),0) -> 0 | F42: =IF(AND($C$42=1,OR($D$42="",F$29>=$D$42)),MAX(0,MIN(F40-F41,F$31-(F36))),0) -> 0 | G42: =IF(AND($C$42=1,OR($D$42="",G$29>=$D$42)),MAX(0,MIN(G40-G41,G$31-(G36))),0) -> 0 | H42: =IF(AND($C$42=1,OR($D$42="",H$29>=$D$42)),MAX(0,MIN(H40-H41,H$31-(H36))),0) -> 0 | I42: =IF(AND($C$42=1,OR($D$42="",I$29>=$D$42)),MAX(0,MIN(I40-I41,I$31-(I36))),0) -> 0 | J42: =IF(AND($C$42=1,OR($D$42="",J$29>=$D$42)),MAX(0,MIN(J40-J41,J$31-(J36))),0) -> 0 | K42: =IF(AND($C$42=1,OR($D$42="",K$29>=$D$42)),MAX(0,MIN(K40-K41,K$31-(K36))),0) -> 0 | L42: =IF(AND($C$42=1,OR($D$42="",L$29>=$D$42)),MAX(0,MIN(L40-L41,L$31-(L36))),0) -> 0 | ... DT42: =IF(AND($C$42=1,OR($D$42="",DT$29>=$D$42)),MAX(0,MIN(DT40-DT41,DT$31-(DT36))),0) -> 0
B43: Saldo | C43: inicial | D43: =IF($C$44=0,D44,MAX(0,D44-MAX(0,$C$10-($D$38*$C$38)))) -> 0 | E43: =E40-E41-E42 -> 0 | F43: =F40-F41-F42 -> 0 | G43: =G40-G41-G42 -> 0 | H43: =H40-H41-H42 -> 0 | I43: =I40-I41-I42 -> 0 | J43: =J40-J41-J42 -> 0 | K43: =K40-K41-K42 -> 0 | L43: =L40-L41-L42 -> 0 | ... DT43: =DT40-DT41-DT42 -> 0
C44: =IF(AND(C42=1,OR(D42="",D42<=$C$11)),1,0) -> 0 | D44: =IF(C39=0,0,N(INDEX($D$13:$D$20,C39))) -> 0
...

Sheet Flujo anual
B1: Flujo mes a mes
B2: Entradas, salidas, meses sin ingreso y destino del sobrante para el año del flujo. Pesos de hoy.
E4: =DATE(Supuestos!$C$14,1,1) -> 46388 | F4: =DATE(Supuestos!$C$14,2,1) -> 46419 | G4: =DATE(Supuestos!$C$14,3,1) -> 46447 | H4: =DATE(Supuestos!$C$14,4,1) -> 46478 | I4: =DATE(Supuestos!$C$14,5,1) -> 46508 | J4: =DATE(Supuestos!$C$14,6,1) -> 46539 | K4: =DATE(Supuestos!$C$14,7,1) -> 46569 | L4: =DATE(Supuestos!$C$14,8,1) -> 46600 | M4: =DATE(Supuestos!$C$14,9,1) -> 46631 | N4: =DATE(Supuestos!$C$14,10,1) -> 46661 | O4: =DATE(Supuestos!$C$14,11,1) -> 46692 | P4: =DATE(Supuestos!$C$14,12,1) -> 46722
B5: Concepto | E5: Ene | F5: Feb | G5: Mar | H5: Abr | I5: May | J5: Jun | K5: Jul | L5: Ago | M5: Sep | N5: Oct | O5: Nov | P5: Dic | Q5: Total año
B6: ENTRADAS
B7: Ingresos laborales | E7: =SUMPRODUCT((Ingresos!$C$6:$C$13="Laboral")*Ingresos!$F$6:$F$13*Ingresos!G$6:G$13) -> 0 | F7: =SUMPRODUCT((Ingresos!$C$6:$C$13="Laboral")*Ingresos!$F$6:$F$13*Ingresos!H$6:H$13) -> 0 | G7: =SUMPRODUCT((Ingresos!$C$6:$C$13="Laboral")*Ingresos!$F$6:$F$13*Ingresos!I$6:I$13) -> 0 | H7: =SUMPRODUCT((Ingresos!$C$6:$C$13="Laboral")*Ingresos!$F$6:$F$13*Ingresos!J$6:J$13) -> 0 | I7: =SUMPRODUCT((Ingresos!$C$6:$C$13="Laboral")*Ingresos!$F$6:$F$13*Ingresos!K$6:K$13) -> 0 | J7: =SUMPRODUCT((Ingresos!$C$6:$C$13="Laboral")*Ingresos!$F$6:$F$13*Ingresos!L$6:L$13) -> 0 | K7: =SUMPRODUCT((Ingresos!$C$6:$C$13="Laboral")*Ingresos!$F$6:$F$13*Ingresos!M$6:M$13) -> 0 | L7: =SUMPRODUCT((Ingresos!$C$6:$C$13="Laboral")*Ingresos!$F$6:$F$13*Ingresos!N$6:N$13) -> 0 | ... P7: =SUMPRODUCT((Ingresos!$C$6:$C$13="Laboral")*Ingresos!$F$6:$F$13*Ingresos!R$6:R$13) -> 0 | Q7: =SUM(E7:P7) -> 0
B8: Rentas | E8: =SUMPRODUCT((Ingresos!$C$6:$C$13="Renta")*Ingresos!$F$6:$F$13*Ingresos!G$6:G$13) -> 0 | F8: =SUMPRODUCT((Ingresos!$C$6:$C$13="Renta")*Ingresos!$F$6:$F$13*Ingresos!H$6:H$13) -> 0 | G8: =SUMPRODUCT((Ingresos!$C$6:$C$13="Renta")*Ingresos!$F$6:$F$13*Ingresos!I$6:I$13) -> 0 | H8: =SUMPRODUCT((Ingresos!$C$6:$C$13="Renta")*Ingresos!$F$6:$F$13*Ingresos!J$6:J$13) -> 0 | I8: =SUMPRODUCT((Ingresos!$C$6:$C$13="Renta")*Ingresos!$F$6:$F$13*Ingresos!K$6:K$13) -> 0 | J8: =SUMPRODUCT((Ingresos!$C$6:$C$13="Renta")*Ingresos!$F$6:$F$13*Ingresos!L$6:L$13) -> 0 | K8: =SUMPRODUCT((Ingresos!$C$6:$C$13="Renta")*Ingresos!$F$6:$F$13*Ingresos!M$6:M$13) -> 0 | L8: =SUMPRODUCT((Ingresos!$C$6:$C$13="Renta")*Ingresos!$F$6:$F$13*Ingresos!N$6:N$13) -> 0 | ... P8: =SUMPRODUCT((Ingresos!$C$6:$C$13="Renta")*Ingresos!$F$6:$F$13*Ingresos!R$6:R$13) -> 0 | Q8: =SUM(E8:P8) -> 0
B9: Pensión | E9: =SUMPRODUCT((Ingresos!$C$6:$C$13="Pensión")*Ingresos!$F$6:$F$13*Ingresos!G$6:G$13) -> 0 | F9: =SUMPRODUCT((Ingresos!$C$6:$C$13="Pensión")*Ingresos!$F$6:$F$13*Ingresos!H$6:H$13) -> 0 | G9: =SUMPRODUCT((Ingresos!$C$6:$C$13="Pensión")*Ingresos!$F$6:$F$13*Ingresos!I$6:I$13) -> 0 | H9: =SUMPRODUCT((Ingresos!$C$6:$C$13="Pensión")*Ingresos!$F$6:$F$13*Ingresos!J$6:J$13) -> 0 | I9: =SUMPRODUCT((Ingresos!$C$6:$C$13="Pensión")*Ingresos!$F$6:$F$13*Ingresos!K$6:K$13) -> 0 | J9: =SUMPRODUCT((Ingresos!$C$6:$C$13="Pensión")*Ingresos!$F$6:$F$13*Ingresos!L$6:L$13) -> 0 | K9: =SUMPRODUCT((Ingresos!$C$6:$C$13="Pensión")*Ingresos!$F$6:$F$13*Ingresos!M$6:M$13) -> 0 | L9: =SUMPRODUCT((Ingresos!$C$6:$C$13="Pensión")*Ingresos!$F$6:$F$13*Ingresos!N$6:N$13) -> 0 | ... P9: =SUMPRODUCT((Ingresos!$C$6:$C$13="Pensión")*Ingresos!$F$6:$F$13*Ingresos!R$6:R$13) -> 0 | Q9: =SUM(E9:P9) -> 0
B10: Otros ingresos | E10: =SUMPRODUCT((Ingresos!$C$6:$C$13="Otro")*Ingresos!$F$6:$F$13*Ingresos!G$6:G$13) -> 0 | F10: =SUMPRODUCT((Ingresos!$C$6:$C$13="Otro")*Ingresos!$F$6:$F$13*Ingresos!H$6:H$13) -> 0 | G10: =SUMPRODUCT((Ingresos!$C$6:$C$13="Otro")*Ingresos!$F$6:$F$13*Ingresos!I$6:I$13) -> 0 | H10: =SUMPRODUCT((Ingresos!$C$6:$C$13="Otro")*Ingresos!$F$6:$F$13*Ingresos!J$6:J$13) -> 0 | I10: =SUMPRODUCT((Ingresos!$C$6:$C$13="Otro")*Ingresos!$F$6:$F$13*Ingresos!K$6:K$13) -> 0 | J10: =SUMPRODUCT((Ingresos!$C$6:$C$13="Otro")*Ingresos!$F$6:$F$13*Ingresos!L$6:L$13) -> 0 | K10: =SUMPRODUCT((Ingresos!$C$6:$C$13="Otro")*Ingresos!$F$6:$F$13*Ingresos!M$6:M$13) -> 0 | L10: =SUMPRODUCT((Ingresos!$C$6:$C$13="Otro")*Ingresos!$F$6:$F$13*Ingresos!N$6:N$13) -> 0 | ... P10: =SUMPRODUCT((Ingresos!$C$6:$C$13="Otro")*Ingresos!$F$6:$F$13*Ingresos!R$6:R$13) -> 0 | Q10: =SUM(E10:P10) -> 0
B11: Total entradas | E11: =SUM(E7:E10) -> 0 | F11: =SUM(F7:F10) -> 0 | G11: =SUM(G7:G10) -> 0 | H11: =SUM(H7:H10) -> 0 | I11: =SUM(I7:I10) -> 0 | J11: =SUM(J7:J10) -> 0 | K11: =SUM(K7:K10) -> 0 | L11: =SUM(L7:L10) -> 0 | ... P11: =SUM(P7:P10) -> 0 | Q11: =SUM(E11:P11) -> 0
B12: SALIDAS
B13: Seguridad social | E13: =Presupuesto!$I$96*Ingresos!G$17 -> 0 | F13: =Presupuesto!$I$96*Ingresos!H$17 -> 0 | G13: =Presupuesto!$I$96*Ingresos!I$17 -> 0 | H13: =Presupuesto!$I$96*Ingresos!J$17 -> 0 | I13: =Presupuesto!$I$96*Ingresos!K$17 -> 0 | J13: =Presupuesto!$I$96*Ingresos!L$17 -> 0 | K13: =Presupuesto!$I$96*Ingresos!M$17 -> 0 | L13: =Presupuesto!$I$96*Ingresos!N$17 -> 0 | ... P13: =Presupuesto!$I$96*Ingresos!R$17 -> 0 | Q13: =SUM(E13:P13) -> 0
B14: Pagos directos | E14: =Presupuesto!$I$90 -> 0 | F14: =Presupuesto!$I$90 -> 0 | G14: =Presupuesto!$I$90 -> 0 | H14: =Presupuesto!$I$90 -> 0 | I14: =Presupuesto!$I$90 -> 0 | J14: =Presupuesto!$I$90 -> 0 | K14: =Presupuesto!$I$90 -> 0 | L14: =Presupuesto!$I$90 -> 0 | ... P14: =Presupuesto!$I$90 -> 0 | Q14: =SUM(E14:P14) -> 0
B15: Aportes a bolsillos | E15: =Presupuesto!$I$91 -> 0 | F15: =Presupuesto!$I$91 -> 0 | G15: =Presupuesto!$I$91 -> 0 | H15: =Presupuesto!$I$91 -> 0 | I15: =Presupuesto!$I$91 -> 0 | J15: =Presupuesto!$I$91 -> 0 | K15: =Presupuesto!$I$91 -> 0 | L15: =Presupuesto!$I$91 -> 0 | ... P15: =Presupuesto!$I$91 -> 0 | Q15: =SUM(E15:P15) -> 0
B16: Cuotas de deudas | E16: =Presupuesto!$I$93 -> 0 | F16: =Presupuesto!$I$93 -> 0 | G16: =Presupuesto!$I$93 -> 0 | H16: =Presupuesto!$I$93 -> 0 | I16: =Presupuesto!$I$93 -> 0 | J16: =Presupuesto!$I$93 -> 0 | K16: =Presupuesto!$I$93 -> 0 | L16: =Presupuesto!$I$93 -> 0 | ... P16: =Presupuesto!$I$93 -> 0 | Q16: =SUM(E16:P16) -> 0
B17: Ahorro programado | E17: =Presupuesto!$I$94 -> 0 | F17: =Presupuesto!$I$94 -> 0 | G17: =Presupuesto!$I$94 -> 0 | H17: =Presupuesto!$I$94 -> 0 | I17: =Presupuesto!$I$94 -> 0 | J17: =Presupuesto!$I$94 -> 0 | K17: =Presupuesto!$I$94 -> 0 | L17: =Presupuesto!$I$94 -> 0 | ... P17: =Presupuesto!$I$94 -> 0 | Q17: =SUM(E17:P17) -> 0
B18: Total salidas | E18: =SUM(E13:E17) -> 0 | F18: =SUM(F13:F17) -> 0 | G18: =SUM(G13:G17) -> 0 | H18: =SUM(H13:H17) -> 0 | I18: =SUM(I13:I17) -> 0 | J18: =SUM(J13:J17) -> 0 | K18: =SUM(K13:K17) -> 0 | L18: =SUM(L13:L17) -> 0 | ... P18: =SUM(P13:P17) -> 0 | Q18: =SUM(E18:P18) -> 0
B19: Balance del mes | E19: =E11-E18 -> 0 | F19: =F11-F18 -> 0 | G19: =G11-G18 -> 0 | H19: =H11-H18 -> 0 | I19: =I11-I18 -> 0 | J19: =J11-J18 -> 0 | K19: =K11-K18 -> 0 | L19: =L11-L18 -> 0 | ... P19: =P11-P18 -> 0 | Q19: =SUM(E19:P19) -> 0 | S19: Meses sin ingreso (cálculo) | T19: Valor
B20: Uso del bolsillo de meses sin ingreso | E20: =MAX(0,-E19)*$T$27 -> 0 | F20: =MAX(0,-F19)*$T$27 -> 0 | G20: =MAX(0,-G19)*$T$27 -> 0 | H20: =MAX(0,-H19)*$T$27 -> 0 | I20: =MAX(0,-I19)*$T$27 -> 0 | J20: =MAX(0,-J19)*$T$27 -> 0 | K20: =MAX(0,-K19)*$T$27 -> 0 | L20: =MAX(0,-L19)*$T$27 -> 0 | ... P20: =MAX(0,-P19)*$T$27 -> 0 | Q20: =SUM(E20:P20) -> 0 | S20: Faltante total de los meses en rojo | T20: =-SUMIF(E19:P19,"<0") -> 0
B21: Aporte al bolsillo de meses sin ingreso | E21: =IF(E19>0,IF($T$24>=$T$23,$T$23,IF($T$21=0,0,$T$26*E19/$T$21)),0) -> 0 | F21: =IF(F19>0,IF($T$24>=$T$23,$T$23,IF($T$21=0,0,$T$26*F19/$T$21)),0) -> 0 | G21: =IF(G19>0,IF($T$24>=$T$23,$T$23,IF($T$21=0,0,$T$26*G19/$T$21)),0) -> 0 | H21: =IF(H19>0,IF($T$24>=$T$23,$T$23,IF($T$21=0,0,$T$26*H19/$T$21)),0) -> 0 | I21: =IF(I19>0,IF($T$24>=$T$23,$T$23,IF($T$21=0,0,$T$26*I19/$T$21)),0) -> 0 | J21: =IF(J19>0,IF($T$24>=$T$23,$T$23,IF($T$21=0,0,$T$26*J19/$T$21)),0) -> 0 | K21: =IF(K19>0,IF($T$24>=$T$23,$T$23,IF($T$21=0,0,$T$26*K19/$T$21)),0) -> 0 | L21: =IF(L19>0,IF($T$24>=$T$23,$T$23,IF($T$21=0,0,$T$26*L19/$T$21)),0) -> 0 | ... P21: =IF(P19>0,IF($T$24>=$T$23,$T$23,IF($T$21=0,0,$T$26*P19/$T$21)),0) -> 0 | Q21: =SUM(E21:P21) -> 0 | S21: Suma de balances positivos | T21: =SUMIF(E19:P19,">0") -> 0
B22: Sobrante del mes | E22: =E19+E20-E21 -> 0 | F22: =F19+F20-F21 -> 0 | G22: =G19+G20-G21 -> 0 | H22: =H19+H20-H21 -> 0 | I22: =I19+I20-I21 -> 0 | J22: =J19+J20-J21 -> 0 | K22: =K19+K20-K21 -> 0 | L22: =L19+L20-L21 -> 0 | ... P22: =P19+P20-P21 -> 0 | Q22: =SUM(E22:P22) -> 0 | S22: Meses con balance positivo | T22: =COUNTIF(E19:P19,">0") -> 0
B23: DESTINO DEL SOBRANTE | S23: Aporte igual por mes positivo | T23: =IF(T22=0,0,T26/T22) -> 0
B24: Abono extra a deudas | E24: =IF(Deudas!$C$23="Sí",MAX(0,E22)*Supuestos!$C$25,0) -> 0 | F24: =IF(Deudas!$C$23="Sí",MAX(0,F22)*Supuestos!$C$25,0) -> 0 | G24: =IF(Deudas!$C$23="Sí",MAX(0,G22)*Supuestos!$C$25,0) -> 0 | H24: =IF(Deudas!$C$23="Sí",MAX(0,H22)*Supuestos!$C$25,0) -> 0 | I24: =IF(Deudas!$C$23="Sí",MAX(0,I22)*Supuestos!$C$25,0) -> 0 | J24: =IF(Deudas!$C$23="Sí",MAX(0,J22)*Supuestos!$C$25,0) -> 0 | K24: =IF(Deudas!$C$23="Sí",MAX(0,K22)*Supuestos!$C$25,0) -> 0 | L24: =IF(Deudas!$C$23="Sí",MAX(0,L22)*Supuestos!$C$25,0) -> 0 | ... P24: =IF(Deudas!$C$23="Sí",MAX(0,P22)*Supuestos!$C$25,0) -> 0 | Q24: =SUM(E24:P24) -> 0 | S24: Menor balance positivo | T24: =IF(T22=0,0,_xlfn.MINIFS(E19:P19,E19:P19,">0")) -> 0
B25: Inversión | E25: =IF(Deudas!$C$23="Sí",0,MAX(0,E22)*Supuestos!$C$42) -> 0 | F25: =IF(Deudas!$C$23="Sí",0,MAX(0,F22)*Supuestos!$C$42) -> 0 | G25: =IF(Deudas!$C$23="Sí",0,MAX(0,G22)*Supuestos!$C$42) -> 0 | H25: =IF(Deudas!$C$23="Sí",0,MAX(0,H22)*Supuestos!$C$42) -> 0 | I25: =IF(Deudas!$C$23="Sí",0,MAX(0,I22)*Supuestos!$C$42) -> 0 | J25: =IF(Deudas!$C$23="Sí",0,MAX(0,J22)*Supuestos!$C$42) -> 0 | K25: =IF(Deudas!$C$23="Sí",0,MAX(0,K22)*Supuestos!$C$42) -> 0 | L25: =IF(Deudas!$C$23="Sí",0,MAX(0,L22)*Supuestos!$C$42) -> 0 | ... P25: =IF(Deudas!$C$23="Sí",0,MAX(0,P22)*Supuestos!$C$42) -> 0 | Q25: =SUM(E25:P25) -> 0 | S25: Método de aporte | T25: =IF(T20=0,"No aplica",IF(T24>=T23,"Aporte igual","Aporte proporcional")) -> No aplica
B26: Margen libre | E26: =E22-E24-E25 -> 0 | F26: =F22-F24-F25 -> 0 | G26: =G22-G24-G25 -> 0 | H26: =H22-H24-H25 -> 0 | I26: =I22-I24-I25 -> 0 | J26: =J22-J24-J25 -> 0 | K26: =K22-K24-K25 -> 0 | L26: =L22-L24-L25 -> 0 | ... P26: =P22-P24-P25 -> 0 | Q26: =SUM(E26:P26) -> 0 | S26: Faltante que alcanza a cubrirse | T26: =MIN(T20,T21) -> 0
B27: CUENTAS POR COBRAR | S27: Cobertura del faltante | T27: =IF(T20=0,1,MIN(1,T21/T20)) -> 1
